Workbook

Sheet 信息总览
A1: 基本信息 | C1: 版本编号：v5 | H1: 备注：85届赛季初期名单v5，核对消费，包括交易，db变化，成长，选秀，解约，消费，随潜，有错联系大直塞报错
A2: 届数 | B2: 85 | D2: 序号 | E2: 级别 | F2: 球队名 | G2: 主教 | H2: 球队人数 | I2: 门将人数 | J2: 工资 | K2: 额外工资 | L2: 税后 | M2: 最终工资 | N2: 8M | O2: 7M | P2: 伪名 | Q2: 总身价 | R2: 平均身价 | S2: 平均CA | T2: 平均PA | U2: 成长总计 | V2: 备注
A3: 本版首届 | B3: 84 | C3: FLA | D3: 1 | E3: 超级 | F3: =C3 -> FLA | G3: 星星 | H3: =COUNTIF(联赛名单!L:L,信息总览!F3) -> 17 | I3: =COUNTIFS(联赛名单!L:L,信息总览!F3,联赛名单!J:J,"GK") -> 2 | J3: =SUMIF(联赛名单!L:L,信息总览!F3,联赛名单!U:U) -> 8.495 | L3: =IF(J3+K3-$B$5>0.3,"拍卖",IF(J3+K3>$B$5,(J3+K3-$B$5)*10+J3,J3+K3)) -> 8.495 | M3: =IF(L3<8,8,L3) -> 8.495 | N3: =COUNTIFS(联赛名单!L:L,信息总览!F3,联赛名单!W:W,"8M") -> 0 | O3: =COUNTIFS(联赛名单!L:L,信息总览!F3,联赛名单!W:W,"7M") -> 2 | P3: =COUNTIFS(联赛名单!L:L,信息总览!F3,联赛名单!W:W,"伪名") -> 5 | Q3: =SUMIF(联赛名单!L:L,信息总览!F3,联赛名单!S:S) -> 87.5 | R3: =Q3/H3 -> 5.1470588 | S3: =SUMIF(联赛名单!L:L,信息总览!F3,联赛名单!G:G)/H3 -> 149.41176 | T3: =SUMIF(联赛名单!L:L,信息总览!F3,联赛名单!I:I)/H3 -> 157.58824 | U3: =SUMIF(联赛名单!L:L,信息总览!F3,联赛名单!G:G)-SUMIF(联赛名单!L:L,信息总览!F3,联赛名单!F:F) -> 59
A4: 成长年龄上限 | B4: =IF(B2-B3>2,23,IF(B2-B3=1,24,25)) -> 24 | C4: Aston Villa | D4: 2 | E4: 超级 | F4: =C4 -> Aston Villa | G4: e指导 | H4: =COUNTIF(联赛名单!L:L,信息总览!F4) -> 20 | I4: =COUNTIFS(联赛名单!L:L,信息总览!F4,联赛名单!J:J,"GK") -> 2 | J4: =SUMIF(联赛名单!L:L,信息总览!F4,联赛名单!U:U) -> 9.22 | L4: =IF(J4+K4-$B$5>0.3,"拍卖",IF(J4+K4>$B$5,(J4+K4-$B$5)*10+J4,J4+K4)) -> 9.22 | M4: =IF(L4<8,8,L4) -> 9.22 | N4: =COUNTIFS(联赛名单!L:L,信息总览!F4,联赛名单!W:W,"8M") -> 1 | O4: =COUNTIFS(联赛名单!L:L,信息总览!F4,联赛名单!W:W,"7M") -> 0 | P4: =COUNTIFS(联赛名单!L:L,信息总览!F4,联赛名单!W:W,"伪名") -> 3 | Q4: =SUMIF(联赛名单!L:L,信息总览!F4,联赛名单!S:S) -> 100 | R4: =Q4/H4 -> 5 | S4: =SUMIF(联赛名单!L:L,信息总览!F4,联赛名单!G:G)/H4 -> 143.55 | T4: =SUMIF(联赛名单!L:L,信息总览!F4,联赛名单!I:I)/H4 -> 157.7 | U4: =SUMIF(联赛名单!L:L,信息总览!F4,联赛名单!G:G)-SUMIF(联赛名单!L:L,信息总览!F4,联赛名单!F:F) -> 78
A5: 超级级工资帽 | B5: 9.4 | C5: Barcelona | D5: 3 | E5: 超级 | F5: =C5 -> Barcelona | G5: cyrus | H5: =COUNTIF(联赛名单!L:L,信息总览!F5) -> 20 | I5: =COUNTIFS(联赛名单!L:L,信息总览!F5,联赛名单!J:J,"GK") -> 2 | J5: =SUMIF(联赛名单!L:L,信息总览!F5,联赛名单!U:U) -> 9.25 | L5: =IF(J5+K5-$B$5>0.3,"拍卖",IF(J5+K5>$B$5,(J5+K5-$B$5)*10+J5,J5+K5)) -> 9.25 | M5: =IF(L5<8,8,L5) -> 9.25 | N5: =COUNTIFS(联赛名单!L:L,信息总览!F5,联赛名单!W:W,"8M") -> 1 | O5: =COUNTIFS(联赛名单!L:L,信息总览!F5,联赛名单!W:W,"7M") -> 2 | P5: =COUNTIFS(联赛名单!L:L,信息总览!F5,联赛名单!W:W,"伪名") -> 3 | Q5: =SUMIF(联赛名单!L:L,信息总览!F5,联赛名单!S:S) -> 100 | R5: =Q5/H5 -> 5 | S5: =SUMIF(联赛名单!L:L,信息总览!F5,联赛名单!G:G)/H5 -> 144.75 | T5: =SUMIF(联赛名单!L:L,信息总览!F5,联赛名单!I:I)/H5 -> 157.95 | U5: =SUMIF(联赛名单!L:L,信息总览!F5,联赛名单!G:G)-SUMIF(联赛名单!L:L,信息总览!F5,联赛名单!F:F) -> 103
A6: 甲级级工资帽 | B6: 8.9 | C6: Bayer 04 | D6: 4 | E6: 超级 | F6: =C6 -> Bayer 04 | G6: AX | H6: =COUNTIF(联赛名单!L:L,信息总览!F6) -> 19 | I6: =COUNTIFS(联赛名单!L:L,信息总览!F6,联赛名单!J:J,"GK") -> 2 | J6: =SUMIF(联赛名单!L:L,信息总览!F6,联赛名单!U:U) -> 8.53 | L6: =IF(J6+K6-$B$5>0.3,"拍卖",IF(J6+K6>$B$5,(J6+K6-$B$5)*10+J6,J6+K6)) -> 8.53 | M6: =IF(L6<8,8,L6) -> 8.53 | N6: =COUNTIFS(联赛名单!L:L,信息总览!F6,联赛名单!W:W,"8M") -> 1 | O6: =COUNTIFS(联赛名单!L:L,信息总览!F6,联赛名单!W:W,"7M") -> 1 | P6: =COUNTIFS(联赛名单!L:L,信息总览!F6,联赛名单!W:W,"伪名") -> 1 | Q6: =SUMIF(联赛名单!L:L,信息总览!F6,联赛名单!S:S) -> 98 | R6: =Q6/H6 -> 5.1578947 | S6: =SUMIF(联赛名单!L:L,信息总览!F6,联赛名单!G:G)/H6 -> 147.15789 | T6: =SUMIF(联赛名单!L:L,信息总览!F6,联赛名单!I:I)/H6 -> 158.94737 | U6: =SUMIF(联赛名单!L:L,信息总览!F6,联赛名单!G:G)-SUMIF(联赛名单!L:L,信息总览!F6,联赛名单!F:F) -> 39
A7: 乙级级工资帽 | B7: 8.6 | C7: Nottm Forest | D7: 5 | E7: 超级 | F7: =C7 -> Nottm Forest | G7: 南国 | H7: =COUNTIF(联赛名单!L:L,信息总览!F7) -> 17 | I7: =COUNTIFS(联赛名单!L:L,信息总览!F7,联赛名单!J:J,"GK") -> 2 | J7: =SUMIF(联赛名单!L:L,信息总览!F7,联赛名单!U:U) -> 9.37 | L7: =IF(J7+K7-$B$5>0.3,"拍卖",IF(J7+K7>$B$5,(J7+K7-$B$5)*10+J7,J7+K7)) -> 9.37 | M7: =IF(L7<8,8,L7) -> 9.37 | N7: =COUNTIFS(联赛名单!L:L,信息总览!F7,联赛名单!W:W,"8M") -> 1 | O7: =COUNTIFS(联赛名单!L:L,信息总览!F7,联赛名单!W:W,"7M") -> 2 | P7: =COUNTIFS(联赛名单!L:L,信息总览!F7,联赛名单!W:W,"伪名") -> 3 | Q7: =SUMIF(联赛名单!L:L,信息总览!F7,联赛名单!S:S) -> 92 | R7: =Q7/H7 -> 5.4117647 | S7: =SUMIF(联赛名单!L:L,信息总览!F7,联赛名单!G:G)/H7 -> 148.52941 | T7: =SUMIF(联赛名单!L:L,信息总览!F7,联赛名单!I:I)/H7 -> 159.94118 | U7: =SUMIF(联赛名单!L:L,信息总览!F7,联赛名单!G:G)-SUMIF(联赛名单!L:L,信息总览!F7,联赛名单!F:F) -> 95
A8: 总工资 | B8: =SUM(M3:M20,M23:M40,M43:M60) -> 446.705 | C8: Borussia Dortmund | D8: 6 | E8: 超级 | F8: =C8 -> Borussia Dortmund | G8: 长臂猿 | H8: =COUNTIF(联赛名单!L:L,信息总览!F8) -> 18 | I8: =COUNTIFS(联赛名单!L:L,信息总览!F8,联赛名单!J:J,"GK") -> 2 | J8: =SUMIF(联赛名单!L:L,信息总览!F8,联赛名单!U:U) -> 9.375 | L8: =IF(J8+K8-$B$5>0.3,"拍卖",IF(J8+K8>$B$5,(J8+K8-$B$5)*10+J8,J8+K8)) -> 9.375 | M8: =IF(L8<8,8,L8) -> 9.375 | N8: =COUNTIFS(联赛名单!L:L,信息总览!F8,联赛名单!W:W,"8M") -> 1 | O8: =COUNTIFS(联赛名单!L:L,信息总览!F8,联赛名单!W:W,"7M") -> 2 | P8: =COUNTIFS(联赛名单!L:L,信息总览!F8,联赛名单!W:W,"伪名") -> 2 | Q8: =SUMIF(联赛名单!L:L,信息总览!F8,联赛名单!S:S) -> 98.5 | R8: =Q8/H8 -> 5.4722222 | S8: =SUMIF(联赛名单!L:L,信息总览!F8,联赛名单!G:G)/H8 -> 152.5 | T8: =SUMIF(联赛名单!L:L,信息总览!F8,联赛名单!I:I)/H8 -> 160.5 | U8: =SUMIF(联赛名单!L:L,信息总览!F8,联赛名单!G:G)-SUMIF(联赛名单!L:L,信息总览!F8,联赛名单!F:F) -> 56
A9: 总平均工资 | B9: =B8/54 -> 8.2723148 | C9: Everton | D9: 7 | E9: 超级 | F9: =C9 -> Everton | G9: 一笑 | H9: =COUNTIF(联赛名单!L:L,信息总览!F9) -> 20 | I9: =COUNTIFS(联赛名单!L:L,信息总览!F9,联赛名单!J:J,"GK") -> 2 | J9: =SUMIF(联赛名单!L:L,信息总览!F9,联赛名单!U:U) -> 6.485 | L9: =IF(J9+K9-$B$5>0.3,"拍卖",IF(J9+K9>$B$5,(J9+K9-$B$5)*10+J9,J9+K9)) -> 6.485 | M9: =IF(L9<8,8,L9) -> 8 | N9: =COUNTIFS(联赛名单!L:L,信息总览!F9,联赛名单!W:W,"8M") -> 1 | O9: =COUNTIFS(联赛名单!L:L,信息总览!F9,联赛名单!W:W,"7M") -> 0 | P9: =COUNTIFS(联赛名单!L:L,信息总览!F9,联赛名单!W:W,"伪名") -> 0 | Q9: =SUMIF(联赛名单!L:L,信息总览!F9,联赛名单!S:S) -> 82.5 | R9: =Q9/H9 -> 4.125 | S9: =SUMIF(联赛名单!L:L,信息总览!F9,联赛名单!G:G)/H9 -> 140.2 | T9: =SUMIF(联赛名单!L:L,信息总览!F9,联赛名单!I:I)/H9 -> 150.1 | U9: =SUMIF(联赛名单!L:L,信息总览!F9,联赛名单!G:G)-SUMIF(联赛名单!L:L,信息总览!F9,联赛名单!F:F) -> 55
A10: 总身价 | B10: =SUM(Q23:Q40,Q3:Q20,Q43:Q60) -> 4877.5 | C10: Inter | D10: 8 | E10: 超级 | F10: =C10 -> Inter | G10: 宝哥 | H10: =COUNTIF(联赛名单!L:L,信息总览!F10) -> 18 | I10: =COUNTIFS(联赛名单!L:L,信息总览!F10,联赛名单!J:J,"GK") -> 2 | J10: =SUMIF(联赛名单!L:L,信息总览!F10,联赛名单!U:U) -> 9.425 | L10: =IF(J10+K10-$B$5>0.3,"拍卖",IF(J10+K10>$B$5,(J10+K10-$B$5)*10+J10,J10+K10)) -> 9.675 | M10: =IF(L10<8,8,L10) -> 9.675 | N10: =COUNTIFS(联赛名单!L:L,信息总览!F10,联赛名单!W:W,"8M") -> 1 | O10: =COUNTIFS(联赛名单!L:L,信息总览!F10,联赛名单!W:W,"7M") -> 2 | P10: =COUNTIFS(联赛名单!L:L,信息总览!F10,联赛名单!W:W,"伪名") -> 0 | Q10: =SUMIF(联赛名单!L:L,信息总览!F10,联赛名单!S:S) -> 97.5 | R10: =Q10/H10 -> 5.4166667 | S10: =SUMIF(联赛名单!L:L,信息总览!F10,联赛名单!G:G)/H10 -> 150.72222 | T10: =SUMIF(联赛名单!L:L,信息总览!F10,联赛名单!I:I)/H10 -> 159.05556 | U10: =SUMIF(联赛名单!L:L,信息总览!F10,联赛名单!G:G)-SUMIF(联赛名单!L:L,信息总览!F10,联赛名单!F:F) -> 39
A11: 总平均身价 | B11: =SUM(R3:R20,R23:R40,R43:R60) -> 261.35877 | C11: Juventus | D11: 9 | E11: 超级 | F11: =C11 -> Juventus | G11: 幽灵 | H11: =COUNTIF(联赛名单!L:L,信息总览!F11) -> 18 | I11: =COUNTIFS(联赛名单!L:L,信息总览!F11,联赛名单!J:J,"GK") -> 2 | J11: =SUMIF(联赛名单!L:L,信息总览!F11,联赛名单!U:U) -> 9.38 | L11: =IF(J11+K11-$B$5>0.3,"拍卖",IF(J11+K11>$B$5,(J11+K11-$B$5)*10+J11,J11+K11)) -> 9.38 | M11: =IF(L11<8,8,L11) -> 9.38 | N11: =COUNTIFS(联赛名单!L:L,信息总览!F11,联赛名单!W:W,"8M") -> 0 | O11: =COUNTIFS(联赛名单!L:L,信息总览!F11,联赛名单!W:W,"7M") -> 2 | P11: =COUNTIFS(联赛名单!L:L,信息总览!F11,联赛名单!W:W,"伪名") -> 3 | Q11: =SUMIF(联赛名单!L:L,信息总览!F11,联赛名单!S:S) -> 98.5 | R11: =Q11/H11 -> 5.4722222 | S11: =SUMIF(联赛名单!L:L,信息总览!F11,联赛名单!G:G)/H11 -> 151.66667 | T11: =SUMIF(联赛名单!L:L,信息总览!F11,联赛名单!I:I)/H11 -> 158.55556 | U11: =SUMIF(联赛名单!L:L,信息总览!F11,联赛名单!G:G)-SUMIF(联赛名单!L:L,信息总览!F11,联赛名单!F:F) -> 68
A12: 身价极差 | B12: =MAX(Q3:Q20,Q23:Q40,Q43:Q60)-MIN(Q3:Q20,Q23:Q40,Q43:Q60) -> 30 | C12: Liverpool | D12: 10 | E12: 超级 | F12: =C12 -> Liverpool | G12: 简单 | H12: =COUNTIF(联赛名单!L:L,信息总览!F12) -> 18 | I12: =COUNTIFS(联赛名单!L:L,信息总览!F12,联赛名单!J:J,"GK") -> 2 | J12: =SUMIF(联赛名单!L:L,信息总览!F12,联赛名单!U:U) -> 9.41 | L12: =IF(J12+K12-$B$5>0.3,"拍卖",IF(J12+K12>$B$5,(J12+K12-$B$5)*10+J12,J12+K12)) -> 9.51 | M12: =IF(L12<8,8,L12) -> 9.51 | N12: =COUNTIFS(联赛名单!L:L,信息总览!F12,联赛名单!W:W,"8M") -> 0 | O12: =COUNTIFS(联赛名单!L:L,信息总览!F12,联赛名单!W:W,"7M") -> 0 | P12: =COUNTIFS(联赛名单!L:L,信息总览!F12,联赛名单!W:W,"伪名") -> 6 | Q12: =SUMIF(联赛名单!L:L,信息总览!F12,联赛名单!S:S) -> 99 | R12: =Q12/H12 -> 5.5 | S12: =SUMIF(联赛名单!L:L,信息总览!F12,联赛名单!G:G)/H12 -> 150.88889 | T12: =SUMIF(联赛名单!L:L,信息总览!F12,联赛名单!I:I)/H12 -> 161.11111 | U12: =SUMIF(联赛名单!L:L,信息总览!F12,联赛名单!G:G)-SUMIF(联赛名单!L:L,信息总览!F12,联赛名单!F:F) -> 97
A13: 总平均CA | B13: =SUM(S3:S20,S23:S40,S43:S60) -> 7637.9624 | C13: Man UFC | D13: 11 | E13: 超级 | F13: =C13 -> Man UFC | G13: 包子 | H13: =COUNTIF(联赛名单!L:L,信息总览!F13) -> 19 | I13: =COUNTIFS(联赛名单!L:L,信息总览!F13,联赛名单!J:J,"GK") -> 2 | J13: =SUMIF(联赛名单!L:L,信息总览!F13,联赛名单!U:U) -> 8.84 | L13: =IF(J13+K13-$B$5>0.3,"拍卖",IF(J13+K13>$B$5,(J13+K13-$B$5)*10+J13,J13+K13)) -> 8.84 | M13: =IF(L13<8,8,L13) -> 8.84 | N13: =COUNTIFS(联赛名单!L:L,信息总览!F13,联赛名单!W:W,"8M") -> 1 | O13: =COUNTIFS(联赛名单!L:L,信息总览!F13,联赛名单!W:W,"7M") -> 0 | P13: =COUNTIFS(联赛名单!L:L,信息总览!F13,联赛名单!W:W,"伪名") -> 2 | Q13: =SUMIF(联赛名单!L:L,信息总览!F13,联赛名单!S:S) -> 97 | R13: =Q13/H13 -> 5.1052632 | S13: =SUMIF(联赛名单!L:L,信息总览!F13,联赛名单!G:G)/H13 -> 148 | T13: =SUMIF(联赛名单!L:L,信息总览!F13,联赛名单!I:I)/H13 -> 159.42105 | U13: =SUMIF(联赛名单!L:L,信息总览!F13,联赛名单!G:G)-SUMIF(联赛名单!L:L,信息总览!F13,联赛名单!F:F) -> 84
A14: CA极差 | B14: =MAX(S3:S20,S23:S40,S43:S60)-MIN(S3:S20,S23:S40,S43:S60) -> 31.4 | C14: Southampton | D14: 12 | E14: 超级 | F14: =C14 -> Southampton | G14: 李指导 | H14: =COUNTIF(联赛名单!L:L,信息总览!F14) -> 20 | I14: =COUNTIFS(联赛名单!L:L,信息总览!F14,联赛名单!J:J,"GK") -> 2 | J14: =SUMIF(联赛名单!L:L,信息总览!F14,联赛名单!U:U) -> 8.265 | L14: =IF(J14+K14-$B$5>0.3,"拍卖",IF(J14+K14>$B$5,(J14+K14-$B$5)*10+J14,J14+K14)) -> 8.265 | M14: =IF(L14<8,8,L14) -> 8.265 | N14: =COUNTIFS(联赛名单!L:L,信息总览!F14,联赛名单!W:W,"8M") -> 1 | O14: =COUNTIFS(联赛名单!L:L,信息总览!F14,联赛名单!W:W,"7M") -> 0 | P14: =COUNTIFS(联赛名单!L:L,信息总览!F14,联赛名单!W:W,"伪名") -> 2 | Q14: =SUMIF(联赛名单!L:L,信息总览!F14,联赛名单!S:S) -> 94.5 | R14: =Q14/H14 -> 4.725 | S14: =SUMIF(联赛名单!L:L,信息总览!F14,联赛名单!G:G)/H14 -> 142.4 | T14: =SUMIF(联赛名单!L:L,信息总览!F14,联赛名单!I:I)/H14 -> 152.45 | U14: =SUMIF(联赛名单!L:L,信息总览!F14,联赛名单!G:G)-SUMIF(联赛名单!L:L,信息总览!F14,联赛名单!F:F) -> 104
A15: 总平均PA | B15: =SUM(T3:T20,T23:T40,T43:T60) -> 8472.0481 | C15: Tottenham | D15: 13 | E15: 超级 | F15: =C15 -> Tottenham | G15: 小R | H15: =COUNTIF(联赛名单!L:L,信息总览!F15) -> 20 | I15: =COUNTIFS(联赛名单!L:L,信息总览!F15,联赛名单!J:J,"GK") -> 2 | J15: =SUMIF(联赛名单!L:L,信息总览!F15,联赛名单!U:U) -> 8.945 | L15: =IF(J15+K15-$B$5>0.3,"拍卖",IF(J15+K15>$B$5,(J15+K15-$B$5)*10+J15,J15+K15)) -> 8.945 | M15: =IF(L15<8,8,L15) -> 8.945 | N15: =COUNTIFS(联赛名单!L:L,信息总览!F15,联赛名单!W:W,"8M") -> 1 | O15: =COUNTIFS(联赛名单!L:L,信息总览!F15,联赛名单!W:W,"7M") -> 0 | P15: =COUNTIFS(联赛名单!L:L,信息总览!F15,联赛名单!W:W,"伪名") -> 3 | Q15: =SUMIF(联赛名单!L:L,信息总览!F15,联赛名单!S:S) -> 100.5 | R15: =Q15/H15 -> 5.025 | S15: =SUMIF(联赛名单!L:L,信息总览!F15,联赛名单!G:G)/H15 -> 144.7 | T15: =SUMIF(联赛名单!L:L,信息总览!F15,联赛名单!I:I)/H15 -> 157.6 | U15: =SUMIF(联赛名单!L:L,信息总览!F15,联赛名单!G:G)-SUMIF(联赛名单!L:L,信息总览!F15,联赛名单!F:F) -> 116
A16: PA极差 | B16: =MAX(T3:T20,T23:T40,T43:T60)-MIN(T3:T20,T23:T40,T43:T60) -> 12.981424 | C16: FC Bayern | D16: 14 | E16: 超级 | F16: =C16 -> FC Bayern | G16: 杰拉德 | H16: =COUNTIF(联赛名单!L:L,信息总览!F16) -> 20 | I16: =COUNTIFS(联赛名单!L:L,信息总览!F16,联赛名单!J:J,"GK") -> 2 | J16: =SUMIF(联赛名单!L:L,信息总览!F16,联赛名单!U:U) -> 8.575 | L16: =IF(J16+K16-$B$5>0.3,"拍卖",IF(J16+K16>$B$5,(J16+K16-$B$5)*10+J16,J16+K16)) -> 8.575 | M16: =IF(L16<8,8,L16) -> 8.575 | N16: =COUNTIFS(联赛名单!L:L,信息总览!F16,联赛名单!W:W,"8M") -> 1 | O16: =COUNTIFS(联赛名单!L:L,信息总览!F16,联赛名单!W:W,"7M") -> 0 | P16: =COUNTIFS(联赛名单!L:L,信息总览!F16,联赛名单!W:W,"伪名") -> 3 | Q16: =SUMIF(联赛名单!L:L,信息总览!F16,联赛名单!S:S) -> 94.5 | R16: =Q16/H16 -> 4.725 | S16: =SUMIF(联赛名单!L:L,信息总览!F16,联赛名单!G:G)/H16 -> 138.05 | T16: =SUMIF(联赛名单!L:L,信息总览!F16,联赛名单!I:I)/H16 -> 158.45 | U16: =SUMIF(联赛名单!L:L,信息总览!F16,联赛名单!G:G)-SUMIF(联赛名单!L:L,信息总览!F16,联赛名单!F:F) -> 104
A17: 总平均成长 | B17: =SUM(U43,U43:U60,U23:U40,U3:U20)/54 -> 83.277778 | C17: R. Madrid | D17: 15 | E17: 超级 | F17: =C17 -> R. Madrid | G17: 小刑 | H17: =COUNTIF(联赛名单!L:L,信息总览!F17) -> 17 | I17: =COUNTIFS(联赛名单!L:L,信息总览!F17,联赛名单!J:J,"GK") -> 2 | J17: =SUMIF(联赛名单!L:L,信息总览!F17,联赛名单!U:U) -> 9.34 | L17: =IF(J17+K17-$B$5>0.3,"拍卖",IF(J17+K17>$B$5,(J17+K17-$B$5)*10+J17,J17+K17)) -> 9.34 | M17: =IF(L17<8,8,L17) -> 9.34 | N17: =COUNTIFS(联赛名单!L:L,信息总览!F17,联赛名单!W:W,"8M") -> 1 | O17: =COUNTIFS(联赛名单!L:L,信息总览!F17,联赛名单!W:W,"7M") -> 1 | P17: =COUNTIFS(联赛名单!L:L,信息总览!F17,联赛名单!W:W,"伪名") -> 3 | Q17: =SUMIF(联赛名单!L:L,信息总览!F17,联赛名单!S:S) -> 94 | R17: =Q17/H17 -> 5.5294118 | S17: =SUMIF(联赛名单!L:L,信息总览!F17,联赛名单!G:G)/H17 -> 151.70588 | T17: =SUMIF(联赛名单!L:L,信息总览!F17,联赛名单!I:I)/H17 -> 160.64706 | U17: =SUMIF(联赛名单!L:L,信息总览!F17,联赛名单!G:G)-SUMIF(联赛名单!L:L,信息总览!F17,联赛名单!F:F) -> 106
A18: 全新工资系数 | C18: Schalke 04 | D18: 16 | E18: 超级 | F18: =C18 -> Schalke 04 | G18: 梅尔 | H18: =COUNTIF(联赛名单!L:L,信息总览!F18) -> 19 | I18: =COUNTIFS(联赛名单!L:L,信息总览!F18,联赛名单!J:J,"GK") -> 2 | J18: =SUMIF(联赛名单!L:L,信息总览!F18,联赛名单!U:U) -> 7.895 | L18: =IF(J18+K18-$B$5>0.3,"拍卖",IF(J18+K18>$B$5,(J18+K18-$B$5)*10+J18,J18+K18)) -> 7.895 | M18: =IF(L18<8,8,L18) -> 8 | N18: =COUNTIFS(联赛名单!L:L,信息总览!F18,联赛名单!W:W,"8M") -> 0 | O18: =COUNTIFS(联赛名单!L:L,信息总览!F18,联赛名单!W:W,"7M") -> 1 | P18: =COUNTIFS(联赛名单!L:L,信息总览!F18,联赛名单!W:W,"伪名") -> 2 | Q18: =SUMIF(联赛名单!L:L,信息总览!F18,联赛名单!S:S) -> 92.5 | R18: =Q18/H18 -> 4.8684211 | S18: =SUMIF(联赛名单!L:L,信息总览!F18,联赛名单!G:G)/H18 -> 143.10526 | T18: =SUMIF(联赛名单!L:L,信息总览!F18,联赛名单!I:I)/H18 -> 154.26316 | U18: =SUMIF(联赛名单!L:L,信息总览!F18,联赛名单!G:G)-SUMIF(联赛名单!L:L,信息总览!F18,联赛名单!F:F) -> 70
A19: 8M名额 | B19: 1.5 | C19: Napoli | D19: 17 | E19: 超级 | F19: =C19 -> Napoli | G19: 大头 | H19: =COUNTIF(联赛名单!L:L,信息总览!F19) -> 20 | I19: =COUNTIFS(联赛名单!L:L,信息总览!F19,联赛名单!J:J,"GK") -> 2 | J19: =SUMIF(联赛名单!L:L,信息总览!F19,联赛名单!U:U) -> 8.29 | L19: =IF(J19+K19-$B$5>0.3,"拍卖",IF(J19+K19>$B$5,(J19+K19-$B$5)*10+J19,J19+K19)) -> 8.29 | M19: =IF(L19<8,8,L19) -> 8.29 | N19: =COUNTIFS(联赛名单!L:L,信息总览!F19,联赛名单!W:W,"8M") -> 0 | O19: =COUNTIFS(联赛名单!L:L,信息总览!F19,联赛名单!W:W,"7M") -> 1 | P19: =COUNTIFS(联赛名单!L:L,信息总览!F19,联赛名单!W:W,"伪名") -> 1 | Q19: =SUMIF(联赛名单!L:L,信息总览!F19,联赛名单!S:S) -> 99 | R19: =Q19/H19 -> 4.95 | S19: =SUMIF(联赛名单!L:L,信息总览!F19,联赛名单!G:G)/H19 -> 147.7 | T19: =SUMIF(联赛名单!L:L,信息总览!F19,联赛名单!I:I)/H19 -> 157.2 | U19: =SUMIF(联赛名单!L:L,信息总览!F19,联赛名单!G:G)-SUMIF(联赛名单!L:L,信息总览!F19,联赛名单!F:F) -> 55
A20: 7M名额 | B20: 1.3 | C20: Chelsea | D20: 18 | E20: 超级 | F20: =C20 -> Chelsea | G20: 无铭剑 | H20: =COUNTIF(联赛名单!L:L,信息总览!F20) -> 20 | I20: =COUNTIFS(联赛名单!L:L,信息总览!F20,联赛名单!J:J,"GK") -> 2 | J20: =SUMIF(联赛名单!L:L,信息总览!F20,联赛名单!U:U) -> 9.375 | L20: =IF(J20+K20-$B$5-0.1>0.3,"拍卖",IF(J20+K20>$B$5+0.1,(J20+K20-$B$5)*10+J20,J20+K20)) -> 9.375 | M20: =IF(L20<8,8,L20) -> 9.375 | N20: =COUNTIFS(联赛名单!L:L,信息总览!F20,联赛名单!W:W,"8M") -> 0 | O20: =COUNTIFS(联赛名单!L:L,信息总览!F20,联赛名单!W:W,"7M") -> 2 | P20: =COUNTIFS(联赛名单!L:L,信息总览!F20,联赛名单!W:W,"伪名") -> 3 | Q20: =SUMIF(联赛名单!L:L,信息总览!F20,联赛名单!S:S) -> 97.5 | R20: =Q20/H20 -> 4.875 | S20: =SUMIF(联赛名单!L:L,信息总览!F20,联赛名单!G:G)/H20 -> 143.25 | T20: =SUMIF(联赛名单!L:L,信息总览!F20,联赛名单!I:I)/H20 -> 159.3 | U20: =SUMIF(联赛名单!L:L,信息总览!F20,联赛名单!G:G)-SUMIF(联赛名单!L:L,信息总览!F20,联赛名单!F:F) -> 77 | V20: 额外0.1M工资帽
A21: 可成长名额 | B21: 1.1
A22: 非名PA6M | B22: 0.9
A23: 非名身价1M | B23: 1 | C23: A. Madrid | D23: 1 | E23: 甲级 | F23: =C23 -> A. Madrid | G23: dogking623 | H23: =COUNTIF(联赛名单!L:L,信息总览!F23) -> 19 | I23: =COUNTIFS(联赛名单!L:L,信息总览!F23,联赛名单!J:J,"GK") -> 2 | J23: =SUMIF(联赛名单!L:L,信息总览!F23,联赛名单!U:U) -> 7.85 | L23: =IF(J23+K23-$B$6>0.3,"拍卖",IF(J23+K23>$B$6,(J23+K23-$B$6)*10+J23,J23+K23)) -> 7.85 | M23: =IF(L23<7.5,7.5,L23) -> 7.85 | N23: =COUNTIFS(联赛名单!L:L,信息总览!F23,联赛名单!W:W,"8M") -> 1 | O23: =COUNTIFS(联赛名单!L:L,信息总览!F23,联赛名单!W:W,"7M") -> 0 | P23: =COUNTIFS(联赛名单!L:L,信息总览!F23,联赛名单!W:W,"伪名") -> 3 | Q23: =SUMIF(联赛名单!L:L,信息总览!F23,联赛名单!S:S) -> 87 | R23: =Q23/H23 -> 4.5789474 | S23: =SUMIF(联赛名单!L:L,信息总览!F23,联赛名单!G:G)/H23 -> 139.57895 | T23: =SUMIF(联赛名单!L:L,信息总览!F23,联赛名单!I:I)/H23 -> 154.31579 | U23: =SUMIF(联赛名单!L:L,信息总览!F23,联赛名单!G:G)-SUMIF(联赛名单!L:L,信息总览!F23,联赛名单!F:F) -> 93
A24: 非名其他 | B24: 0.7 | C24: AC Milan | D24: 2 | E24: 甲级 | F24: =C24 -> AC Milan | G24: 陈先生 | H24: =COUNTIF(联赛名单!L:L,信息总览!F24) -> 16 | I24: =COUNTIFS(联赛名单!L:L,信息总览!F24,联赛名单!J:J,"GK") -> 2 | J24: =SUMIF(联赛名单!L:L,信息总览!F24,联赛名单!U:U) -> 5.975 | L24: =IF(J24+K24-$B$6-0.1>0.3,"拍卖",IF(J24+K24>$B$6+0.1,(J24+K24-$B$6)*10+J24,J24+K24)) -> 5.975 | M24: =IF(L24<7.5,7.5,L24) -> 7.5 | N24: =COUNTIFS(联赛名单!L:L,信息总览!F24,联赛名单!W:W,"8M") -> 0 | O24: =COUNTIFS(联赛名单!L:L,信息总览!F24,联赛名单!W:W,"7M") -> 0 | P24: =COUNTIFS(联赛名单!L:L,信息总览!F24,联赛名单!W:W,"伪名") -> 2 | Q24: =SUMIF(联赛名单!L:L,信息总览!F24,联赛名单!S:S) -> 70.5 | R24: =Q24/H24 -> 4.40625 | S24: =SUMIF(联赛名单!L:L,信息总览!F24,联赛名单!G:G)/H24 -> 133.875 | T24: =SUMIF(联赛名单!L:L,信息总览!F24,联赛名单!I:I)/H24 -> 153.625 | U24: =SUMIF(联赛名单!L:L,信息总览!F24,联赛名单!G:G)-SUMIF(联赛名单!L:L,信息总览!F24,联赛名单!F:F) -> 24 | V24: 额外0.1M工资帽
A25: 注：名额GK系数为1 | C25: Hamburger Sport-Verein | D25: 3 | E25: 甲级 | F25: =C25 -> Hamburger Sport-Verein | G25: 小a | H25: =COUNTIF(联赛名单!L:L,信息总览!F25) -> 20 | I25: =COUNTIFS(联赛名单!L:L,信息总览!F25,联赛名单!J:J,"GK") -> 2 | J25: =SUMIF(联赛名单!L:L,信息总览!F25,联赛名单!U:U) -> 8.37 | L25: =IF(J25+K25-$B$6>0.3,"拍卖",IF(J25+K25>$B$6,(J25+K25-$B$6)*10+J25,J25+K25)) -> 8.37 | M25: =IF(L25<7.5,7.5,L25) -> 8.37 | N25: =COUNTIFS(联赛名单!L:L,信息总览!F25,联赛名单!W:W,"8M") -> 0 | O25: =COUNTIFS(联赛名单!L:L,信息总览!F25,联赛名单!W:W,"7M") -> 0 | P25: =COUNTIFS(联赛名单!L:L,信息总览!F25,联赛名单!W:W,"伪名") -> 5 | Q25: =SUMIF(联赛名单!L:L,信息总览!F25,联赛名单!S:S) -> 97 | R25: =Q25/H25 -> 4.85 | S25: =SUMIF(联赛名单!L:L,信息总览!F25,联赛名单!G:G)/H25 -> 144.85 | T25: =SUMIF(联赛名单!L:L,信息总览!F25,联赛名单!I:I)/H25 -> 156.15 | U25: =SUMIF(联赛名单!L:L,信息总览!F25,联赛名单!G:G)-SUMIF(联赛名单!L:L,信息总览!F25,联赛名单!F:F) -> 82
C26: A. Bilbao | D26: 4 | E26: 甲级 | F26: =C26 -> A. Bilbao | G26: 大V | H26: =COUNTIF(联赛名单!L:L,信息总览!F26) -> 17 | I26: =COUNTIFS(联赛名单!L:L,信息总览!F26,联赛名单!J:J,"GK") -> 2 | J26: =SUMIF(联赛名单!L:L,信息总览!F26,联赛名单!U:U) -> 8.775 | L26: =IF(J26+K26-$B$6>0.3,"拍卖",IF(J26+K26>$B$6,(J26+K26-$B$6)*10+J26,J26+K26)) -> 8.775 | M26: =IF(L26<7.5,7.5,L26) -> 8.775 | N26: =COUNTIFS(联赛名单!L:L,信息总览!F26,联赛名单!W:W,"8M") -> 1 | O26: =COUNTIFS(联赛名单!L:L,信息总览!F26,联赛名单!W:W,"7M") -> 1 | P26: =COUNTIFS(联赛名单!L:L,信息总览!F26,联赛名单!W:W,"伪名") -> 4 | Q26: =SUMIF(联赛名单!L:L,信息总览!F26,联赛名单!S:S) -> 88.5 | R26: =Q26/H26 -> 5.2058824 | S26: =SUMIF(联赛名单!L:L,信息总览!F26,联赛名单!G:G)/H26 -> 143.29412 | T26: =SUMIF(联赛名单!L:L,信息总览!F26,联赛名单!I:I)/H26 -> 161.82353 | U26: =SUMIF(联赛名单!L:L,信息总览!F26,联赛名单!G:G)-SUMIF(联赛名单!L:L,信息总览!F26,联赛名单!F:F) -> 149
C27: Celtic | D27: 5 | E27: 甲级 | F27: =C27 -> Celtic | G27: 天王 | H27: =COUNTIF(联赛名单!L:L,信息总览!F27) -> 19 | I27: =COUNTIFS(联赛名单!L:L,信息总览!F27,联赛名单!J:J,"GK") -> 2 | J27: =SUMIF(联赛名单!L:L,信息总览!F27,联赛名单!U:U) -> 8.625 | L27: =IF(J27+K27-$B$6>0.3,"拍卖",IF(J27+K27>$B$6,(J27+K27-$B$6)*10+J27,J27+K27)) -> 8.625 | M27: =IF(L27<7.5,7.5,L27) -> 8.625 | N27: =COUNTIFS(联赛名单!L:L,信息总览!F27,联赛名单!W:W,"8M") -> 0 | O27: =COUNTIFS(联赛名单!L:L,信息总览!F27,联赛名单!W:W,"7M") -> 1 | P27: =COUNTIFS(联赛名单!L:L,信息总览!F27,联赛名单!W:W,"伪名") -> 4 | Q27: =SUMIF(联赛名单!L:L,信息总览!F27,联赛名单!S:S) -> 95.5 | R27: =Q27/H27 -> 5.0263158 | S27: =SUMIF(联赛名单!L:L,信息总览!F27,联赛名单!G:G)/H27 -> 144.84211 | T27: =SUMIF(联赛名单!L:L,信息总览!F27,联赛名单!I:I)/H27 -> 157 | U27: =SUMIF(联赛名单!L:L,信息总览!F27,联赛名单!G:G)-SUMIF(联赛名单!L:L,信息总览!F27,联赛名单!F:F) -> 112
C28: RB Leipzig | D28: 6 | E28: 甲级 | F28: =C28 -> RB Leipzig | G28: 索夜 | H28: =COUNTIF(联赛名单!L:L,信息总览!F28) -> 20 | I28: =COUNTIFS(联赛名单!L:L,信息总览!F28,联赛名单!J:J,"GK") -> 2 | J28: =SUMIF(联赛名单!L:L,信息总览!F28,联赛名单!U:U) -> 7.615 | L28: =IF(J28+K28-$B$6>0.3,"拍卖",IF(J28+K28>$B$6,(J28+K28-$B$6)*10+J28,J28+K28)) -> 7.615 | M28: =IF(L28<7.5,7.5,L28) -> 7.615 | N28: =COUNTIFS(联赛名单!L:L,信息总览!F28,联赛名单!W:W,"8M") -> 1 | O28: =COUNTIFS(联赛名单!L:L,信息总览!F28,联赛名单!W:W,"7M") -> 0 | P28: =COUNTIFS(联赛名单!L:L,信息总览!F28,联赛名单!W:W,"伪名") -> 2 | Q28: =SUMIF(联赛名单!L:L,信息总览!F28,联赛名单!S:S) -> 94.5 | R28: =Q28/H28 -> 4.725 | S28: =SUMIF(联赛名单!L:L,信息总览!F28,联赛名单!G:G)/H28 -> 140.6 | T28: =SUMIF(联赛名单!L:L,信息总览!F28,联赛名单!I:I)/H28 -> 153.45 | U28: =SUMIF(联赛名单!L:L,信息总览!F28,联赛名单!G:G)-SUMIF(联赛名单!L:L,信息总览!F28,联赛名单!F:F) -> 126
C29: Sunderland | D29: 7 | E29: 甲级 | F29: =C29 -> Sunderland | G29: DTA | H29: =COUNTIF(联赛名单!L:L,信息总览!F29) -> 19 | I29: =COUNTIFS(联赛名单!L:L,信息总览!F29,联赛名单!J:J,"GK") -> 2 | J29: =SUMIF(联赛名单!L:L,信息总览!F29,联赛名单!U:U) -> 8.89 | L29: =IF(J29+K29-$B$6-0.1>0.3,"拍卖",IF(J29+K29>$B$6+0.1,(J29+K29-$B$6)*10+J29,J29+K29)) -> 8.89 | M29: =IF(L29<7.5,7.5,L29) -> 8.89 | N29: =COUNTIFS(联赛名单!L:L,信息总览!F29,联赛名单!W:W,"8M") -> 0 | O29: =COUNTIFS(联赛名单!L:L,信息总览!F29,联赛名单!W:W,"7M") -> 1 | P29: =COUNTIFS(联赛名单!L:L,信息总览!F29,联赛名单!W:W,"伪名") -> 4 | Q29: =SUMIF(联赛名单!L:L,信息总览!F29,联赛名单!S:S) -> 94 | R29: =Q29/H29 -> 4.9473684 | S29: =SUMIF(联赛名单!L:L,信息总览!F29,联赛名单!G:G)/H29 -> 144.15789 | T29: =SUMIF(联赛名单!L:L,信息总览!F29,联赛名单!I:I)/H29 -> 155.78947 | U29: =SUMIF(联赛名单!L:L,信息总览!F29,联赛名单!G:G)-SUMIF(联赛名单!L:L,信息总览!F29,联赛名单!F:F) -> 110 | V29: 额外0.1M工资帽
C30: West Ham | D30: 8 | E30: 甲级 | F30: =C30 -> West Ham | G30: heyes | H30: =COUNTIF(联赛名单!L:L,信息总览!F30) -> 19 | I30: =COUNTIFS(联赛名单!L:L,信息总览!F30,联赛名单!J:J,"GK") -> 2 | J30: =SUMIF(联赛名单!L:L,信息总览!F30,联赛名单!U:U) -> 7.51 | L30: =IF(J30+K30-$B$6>0.3,"拍卖",IF(J30+K30>$B$6,(J30+K30-$B$6)*10+J30,J30+K30)) -> 7.51 | M30: =IF(L30<7.5,7.5,L30) -> 7.51 | N30: =COUNTIFS(联赛名单!L:L,信息总览!F30,联赛名单!W:W,"8M") -> 0 | O30: =COUNTIFS(联赛名单!L:L,信息总览!F30,联赛名单!W:W,"7M") -> 0 | P30: =COUNTIFS(联赛名单!L:L,信息总览!F30,联赛名单!W:W,"伪名") -> 4 | Q30: =SUMIF(联赛名单!L:L,信息总览!F30,联赛名单!S:S) -> 88 | R30: =Q30/H30 -> 4.6315789 | S30: =SUMIF(联赛名单!L:L,信息总览!F30,联赛名单!G:G)/H30 -> 139.47368 | T30: =SUMIF(联赛名单!L:L,信息总览!F30,联赛名单!I:I)/H30 -> 156.84211 | U30: =SUMIF(联赛名单!L:L,信息总览!F30,联赛名单!G:G)-SUMIF(联赛名单!L:L,信息总览!F30,联赛名单!F:F) -> 99
C31: Crystal Palace | D31: 9 | E31: 甲级 | F31: =C31 -> Crystal Palace | G31: 完美 | H31: =COUNTIF(联赛名单!L:L,信息总览!F31) -> 17 | I31: =COUNTIFS(联赛名单!L:L,信息总览!F31,联赛名单!J:J,"GK") -> 2 | J31: =SUMIF(联赛名单!L:L,信息总览!F31,联赛名单!U:U) -> 8.54 | L31: =IF(J31+K31-$B$6>0.3,"拍卖",IF(J31+K31>$B$6,(J31+K31-$B$6)*10+J31,J31+K31)) -> 8.54 | M31: =IF(L31<7.5,7.5,L31) -> 8.54 | N31: =COUNTIFS(联赛名单!L:L,信息总览!F31,联赛名单!W:W,"8M") -> 1 | O31: =COUNTIFS(联赛名单!L:L,信息总览!F31,联赛名单!W:W,"7M") -> 0 | P31: =COUNTIFS(联赛名单!L:L,信息总览!F31,联赛名单!W:W,"伪名") -> 4 | Q31: =SUMIF(联赛名单!L:L,信息总览!F31,联赛名单!S:S) -> 86 | R31: =Q31/H31 -> 5.0588235 | S31: =SUMIF(联赛名单!L:L,信息总览!F31,联赛名单!G:G)/H31 -> 140.70588 | T31: =SUMIF(联赛名单!L:L,信息总览!F31,联赛名单!I:I)/H31 -> 158.35294 | U31: =SUMIF(联赛名单!L:L,信息总览!F31,联赛名单!G:G)-SUMIF(联赛名单!L:L,信息总览!F31,联赛名单!F:F) -> 129
C32: Sporting CP | D32: 10 | E32: 甲级 | F32: =C32 -> Sporting CP | G32: 魔力鸡 | H32: =COUNTIF(联赛名单!L:L,信息总览!F32) -> 19 | I32: =COUNTIFS(联赛名单!L:L,信息总览!F32,联赛名单!J:J,"GK") -> 2 | J32: =SUMIF(联赛名单!L:L,信息总览!F32,联赛名单!U:U) -> 8.73 | L32: =IF(J32+K32-$B$6>0.3,"拍卖",IF(J32+K32>$B$6,(J32+K32-$B$6)*10+J32,J32+K32)) -> 8.73 | M32: =IF(L32<7.5,7.5,L32) -> 8.73 | N32: =COUNTIFS(联赛名单!L:L,信息总览!F32,联赛名单!W:W,"8M") -> 1 | O32: =COUNTIFS(联赛名单!L:L,信息总览!F32,联赛名单!W:W,"7M") -> 0 | P32: =COUNTIFS(联赛名单!L:L,信息总览!F32,联赛名单!W:W,"伪名") -> 4 | Q32: =SUMIF(联赛名单!L:L,信息总览!F32,联赛名单!S:S) -> 93 | R32: =Q32/H32 -> 4.8947368 | S32: =SUMIF(联赛名单!L:L,信息总览!F32,联赛名单!G:G)/H32 -> 140 | T32: =SUMIF(联赛名单!L:L,信息总览!F32,联赛名单!I:I)/H32 -> 156.36842 | U32: =SUMIF(联赛名单!L:L,信息总览!F32,联赛名单!G:G)-SUMIF(联赛名单!L:L,信息总览!F32,联赛名单!F:F) -> 131
C33: Lazio | D33: 11 | E33: 甲级 | F33: =C33 -> Lazio | G33: superS | H33: =COUNTIF(联赛名单!L:L,信息总览!F33) -> 20 | I33: =COUNTIFS(联赛名单!L:L,信息总览!F33,联赛名单!J:J,"GK") -> 2 | J33: =SUMIF(联赛名单!L:L,信息总览!F33,联赛名单!U:U) -> 8.305 | L33: =IF(J33+K33-$B$6>0.3,"拍卖",IF(J33+K33>$B$6,(J33+K33-$B$6)*10+J33,J33+K33)) -> 8.305 | M33: =IF(L33<7.5,7.5,L33) -> 8.305 | N33: =COUNTIFS(联赛名单!L:L,信息总览!F33,联赛名单!W:W,"8M") -> 0 | O33: =COUNTIFS(联赛名单!L:L,信息总览!F33,联赛名单!W:W,"7M") -> 1 | P33: =COUNTIFS(联赛名单!L:L,信息总览!F33,联赛名单!W:W,"伪名") -> 3 | Q33: =SUMIF(联赛名单!L:L,信息总览!F33,联赛名单!S:S) -> 93.5 | R33: =Q33/H33 -> 4.675 | S33: =SUMIF(联赛名单!L:L,信息总览!F33,联赛名单!G:G)/H33 -> 137.1 | T33: =SUMIF(联赛名单!L:L,信息总览!F33,联赛名单!I:I)/H33 -> 154.4 | U33: =SUMIF(联赛名单!L:L,信息总览!F33,联赛名单!G:G)-SUMIF(联赛名单!L:L,信息总览!F33,联赛名单!F:F) -> 74
C34: FK Bodø/Glimt | D34: 12 | E34: 甲级 | F34: =C34 -> FK Bodø/Glimt | G34: PD | H34: =COUNTIF(联赛名单!L:L,信息总览!F34) -> 19 | I34: =COUNTIFS(联赛名单!L:L,信息总览!F34,联赛名单!J:J,"GK") -> 2 | J34: =SUMIF(联赛名单!L:L,信息总览!F34,联赛名单!U:U) -> 8.245 | L34: =IF(J34+K34-$B$6>0.3,"拍卖",IF(J34+K34>$B$6,(J34+K34-$B$6)*10+J34,J34+K34)) -> 8.245 | M34: =IF(L34<7.5,7.5,L34) -> 8.245 | N34: =COUNTIFS(联赛名单!L:L,信息总览!F34,联赛名单!W:W,"8M") -> 0 | O34: =COUNTIFS(联赛名单!L:L,信息总览!F34,联赛名单!W:W,"7M") -> 0 | P34: =COUNTIFS(联赛名单!L:L,信息总览!F34,联赛名单!W:W,"伪名") -> 6 | Q34: =SUMIF(联赛名单!L:L,信息总览!F34,联赛名单!S:S) -> 91.5 | R34: =Q34/H34 -> 4.8157895 | S34: =SUMIF(联赛名单!L:L,信息总览!F34,联赛名单!G:G)/H34 -> 137.89474 | T34: =SUMIF(联赛名单!L:L,信息总览!F34,联赛名单!I:I)/H34 -> 157.68421 | U34: =SUMIF(联赛名单!L:L,信息总览!F34,联赛名单!G:G)-SUMIF(联赛名单!L:L,信息总览!F34,联赛名单!F:F) -> 126
C35: Paris SG | D35: 13 | E35: 甲级 | F35: =C35 -> Paris SG | G35: 拿破仑 | H35: =COUNTIF(联赛名单!L:L,信息总览!F35) -> 20 | I35: =COUNTIFS(联赛名单!L:L,信息总览!F35,联赛名单!J:J,"GK") -> 2 | J35: =SUMIF(联赛名单!L:L,信息总览!F35,联赛名单!U:U) -> 8.27 | L35: =IF(J35+K35-$B$6>0.3,"拍卖",IF(J35+K35>$B$6,(J35+K35-$B$6)*10+J35,J35+K35)) -> 8.27 | M35: =IF(L35<7.5,7.5,L35) -> 8.27 | N35: =COUNTIFS(联赛名单!L:L,信息总览!F35,联赛名单!W:W,"8M") -> 1 | O35: =COUNTIFS(联赛名单!L:L,信息总览!F35,联赛名单!W:W,"7M") -> 0 | P35: =COUNTIFS(联赛名单!L:L,信息总览!F35,联赛名单!W:W,"伪名") -> 1 | Q35: =SUMIF(联赛名单!L:L,信息总览!F35,联赛名单!S:S) -> 92 | R35: =Q35/H35 -> 4.6 | S35: =SUMIF(联赛名单!L:L,信息总览!F35,联赛名单!G:G)/H35 -> 138.5 | T35: =SUMIF(联赛名单!L:L,信息总览!F35,联赛名单!I:I)/H35 -> 154.35 | U35: =SUMIF(联赛名单!L:L,信息总览!F35,联赛名单!G:G)-SUMIF(联赛名单!L:L,信息总览!F35,联赛名单!F:F) -> 122
C36: OM | D36: 14 | E36: 甲级 | F36: =C36 -> OM | G36: fmgamer | H36: =COUNTIF(联赛名单!L:L,信息总览!F36) -> 16 | I36: =COUNTIFS(联赛名单!L:L,信息总览!F36,联赛名单!J:J,"GK") -> 2 | J36: =SUMIF(联赛名单!L:L,信息总览!F36,联赛名单!U:U) -> 8.56 | L36: =IF(J36+K36-$B$6>0.3,"拍卖",IF(J36+K36>$B$6,(J36+K36-$B$6)*10+J36,J36+K36)) -> 8.56 | M36: =IF(L36<7.5,7.5,L36) -> 8.56 | N36: =COUNTIFS(联赛名单!L:L,信息总览!F36,联赛名单!W:W,"8M") -> 0 | O36: =COUNTIFS(联赛名单!L:L,信息总览!F36,联赛名单!W:W,"7M") -> 3 | P36: =COUNTIFS(联赛名单!L:L,信息总览!F36,联赛名单!W:W,"伪名") -> 1 | Q36: =SUMIF(联赛名单!L:L,信息总览!F36,联赛名单!S:S) -> 87 | R36: =Q36/H36 -> 5.4375 | S36: =SUMIF(联赛名单!L:L,信息总览!F36,联赛名单!G:G)/H36 -> 152.1875 | T36: =SUMIF(联赛名单!L:L,信息总览!F36,联赛名单!I:I)/H36 -> 157.125 | U36: =SUMIF(联赛名单!L:L,信息总览!F36,联赛名单!G:G)-SUMIF(联赛名单!L:L,信息总览!F36,联赛名单!F:F) -> 46
C37: AS Roma | D37: 15 | E37: 甲级 | F37: =C37 -> AS Roma | G37: 14 | H37: =COUNTIF(联赛名单!L:L,信息总览!F37) -> 18 | I37: =COUNTIFS(联赛名单!L:L,信息总览!F37,联赛名单!J:J,"GK") -> 2 | J37: =SUMIF(联赛名单!L:L,信息总览!F37,联赛名单!U:U) -> 8.86 | L37: =IF(J37+K37-$B$6>0.3,"拍卖",IF(J37+K37>$B$6,(J37+K37-$B$6)*10+J37,J37+K37)) -> 8.86 | M37: =IF(L37<7.5,7.5,L37) -> 8.86 | N37: =COUNTIFS(联赛名单!L:L,信息总览!F37,联赛名单!W:W,"8M") -> 1 | O37: =COUNTIFS(联赛名单!L:L,信息总览!F37,联赛名单!W:W,"7M") -> 0 | P37: =COUNTIFS(联赛名单!L:L,信息总览!F37,联赛名单!W:W,"伪名") -> 3 | Q37: =SUMIF(联赛名单!L:L,信息总览!F37,联赛名单!S:S) -> 95 | R37: =Q37/H37 -> 5.2777778 | S37: =SUMIF(联赛名单!L:L,信息总览!F37,联赛名单!G:G)/H37 -> 146.27778 | T37: =SUMIF(联赛名单!L:L,信息总览!F37,联赛名单!I:I)/H37 -> 158.38889 | U37: =SUMIF(联赛名单!L:L,信息总览!F37,联赛名单!G:G)-SUMIF(联赛名单!L:L,信息总览!F37,联赛名单!F:F) -> 105
C38: Newcastle | D38: 16 | E38: 甲级 | F38: =C38 -> Newcastle | G38: 金牛 | H38: =COUNTIF(联赛名单!L:L,信息总览!F38) -> 20 | I38: =COUNTIFS(联赛名单!L:L,信息总览!F38,联赛名单!J:J,"GK") -> 2 | J38: =SUMIF(联赛名单!L:L,信息总览!F38,联赛名单!U:U) -> 8.27 | L38: =IF(J38+K38-$B$6>0.3,"拍卖",IF(J38+K38>$B$6,(J38+K38-$B$6)*10+J38,J38+K38)) -> 8.27 | M38: =IF(L38<7.5,7.5,L38) -> 8.27 | N38: =COUNTIFS(联赛名单!L:L,信息总览!F38,联赛名单!W:W,"8M") -> 0 | O38: =COUNTIFS(联赛名单!L:L,信息总览!F38,联赛名单!W:W,"7M") -> 1 | P38: =COUNTIFS(联赛名单!L:L,信息总览!F38,联赛名单!W:W,"伪名") -> 3 | Q38: =SUMIF(联赛名单!L:L,信息总览!F38,联赛名单!S:S) -> 93 | R38: =Q38/H38 -> 4.65 | S38: =SUMIF(联赛名单!L:L,信息总览!F38,联赛名单!G:G)/H38 -> 137.05 | T38: =SUMIF(联赛名单!L:L,信息总览!F38,联赛名单!I:I)/H38 -> 155.2 | U38: =SUMIF(联赛名单!L:L,信息总览!F38,联赛名单!G:G)-SUMIF(联赛名单!L:L,信息总览!F38,联赛名单!F:F) -> 40
C39: Wolverhampton Wanderers | D39: 17 | E39: 甲级 | F39: =C39 -> Wolverhampton Wanderers | G39: lav | H39: =COUNTIF(联赛名单!L:L,信息总览!F39) -> 20 | I39: =COUNTIFS(联赛名单!L:L,信息总览!F39,联赛名单!J:J,"GK") -> 2 | J39: =SUMIF(联赛名单!L:L,信息总览!F39,联赛名单!U:U) -> 8.375 | L39: =IF(J39+K39-$B$6>0.3,"拍卖",IF(J39+K39>$B$6,(J39+K39-$B$6)*10+J39,J39+K39)) -> 8.375 | M39: =IF(L39<7.5,7.5,L39) -> 8.375 | N39: =COUNTIFS(联赛名单!L:L,信息总览!F39,联赛名单!W:W,"8M") -> 0 | O39: =COUNTIFS(联赛名单!L:L,信息总览!F39,联赛名单!W:W,"7M") -> 2 | P39: =COUNTIFS(联赛名单!L:L,信息总览!F39,联赛名单!W:W,"伪名") -> 0 | Q39: =SUMIF(联赛名单!L:L,信息总览!F39,联赛名单!S:S) -> 95.5 | R39: =Q39/H39 -> 4.775 | S39: =SUMIF(联赛名单!L:L,信息总览!F39,联赛名单!G:G)/H39 -> 143.95 | T39: =SUMIF(联赛名单!L:L,信息总览!F39,联赛名单!I:I)/H39 -> 158.45 | U39: =SUMIF(联赛名单!L:L,信息总览!F39,联赛名单!G:G)-SUMIF(联赛名单!L:L,信息总览!F39,联赛名单!F:F) -> 34
C40: Talleres | D40: 18 | E40: 甲级 | F40: =C40 -> Talleres | G40: xx | H40: =COUNTIF(联赛名单!L:L,信息总览!F40) -> 20 | I40: =COUNTIFS(联赛名单!L:L,信息总览!F40,联赛名单!J:J,"GK") -> 2 | J40: =SUMIF(联赛名单!L:L,信息总览!F40,联赛名单!U:U) -> 6.56 | L40: =IF(J40+K40-$B$6>0.3,"拍卖",IF(J40+K40>$B$6,(J40+K40-$B$6)*10+J40,J40+K40)) -> 6.56 | M40: =IF(L40<7.5,7.5,L40) -> 7.5 | N40: =COUNTIFS(联赛名单!L:L,信息总览!F40,联赛名单!W:W,"8M") -> 0 | O40: =COUNTIFS(联赛名单!L:L,信息总览!F40,联赛名单!W:W,"7M") -> 0 | P40: =COUNTIFS(联赛名单!L:L,信息总览!F40,联赛名单!W:W,"伪名") -> 0 | Q40: =SUMIF(联赛名单!L:L,信息总览!F40,联赛名单!S:S) -> 78 | R40: =Q40/H40 -> 3.9 | S40: =SUMIF(联赛名单!L:L,信息总览!F40,联赛名单!G:G)/H40 -> 127.8 | T40: =SUMIF(联赛名单!L:L,信息总览!F40,联赛名单!I:I)/H40 -> 152.95 | U40: =SUMIF(联赛名单!L:L,信息总览!F40,联赛名单!G:G)-SUMIF(联赛名单!L:L,信息总览!F40,联赛名单!F:F) -> 119
...

Sheet 联赛名单
A1: 名额 | B1: 编​号 | C1: 姓​名 | D1: 原年龄 | E1: 年​龄 | F1: 初始CA | G1: 当前CA | H1: 更新CA | I1: PA | J1: 位​置 | K1: 国籍 | L1: 俱乐部 | M1: 级​别 | N1: 身​高 | O1: 体​重 | P1: 初始身价 | Q1: 当前身价 | R1: 潜力身价 | S1: 身价 | T1: 系数 | U1: 工资 | V1: 初始 | W1: 名额
A2: =W2 -> 7M | B2: 24048100 | C2: Dani Olmo | E2: 27 | F2: 165 | G2: 165 | H2: =IFERROR(VLOOKUP(B2,球员对应球队!A:D,4,FALSE)-G2,"") -> 0 | I2: 170 | J2: M/AMRLC | K2: 西班牙 | L2: A. Bilbao | M2: =VLOOKUP(L2,信息总览!C:E,3,FALSE) -> 甲级 | P2: =IF(F2<115,1,INT((F2-95)/10)) -> 7 | Q2: =IF(G2<115,1,INT((G2-95)/10)) -> 7 | R2: =IF(I2<115,1,INT((I2-95)/10)) -> 7 | S2: =IF(E2>信息总览!$B$4,Q2,IF(I2<140,Q2,(Q2+R2)/2)) -> 7 | T2: =IF(AND(J2="GK",W2<>""),0.1,IF(S2=1,0.1,IF((S2+V2)/2=1,0.1,IF(W2="8M",0.15,IF(W2="7M",0.13,IF(W2="伪名",0.11,IF(E2>信息总览!$B$4,IF(INT((G2-95)/10)>5,0.09,0.07),IF(INT((I2-95)/10)>5,0.09,0.07)))))))) -> 0.13 | U2: =S2*T2 -> 0.91 | V2: =IF(E2>25,IF(F2<115,1,INT((F2-95)/10)),(IF(F2<115,1,INT((F2-95)/10))+IF(I2<115,1,INT((I2-95)/10)))/2) -> 7 | W2: =IF(V2>=8,"8M",IF(V2>=7,"7M",IF(E2<=信息总览!$B$4,IF(I2>164,"伪名",""),IF(AND(E2>信息总览!$B$4,E2<26,G2>164),"伪名","")))) -> 7M | X2: =IF(I2<140,0,IF(E2>23,0,I2-G2)) -> 0
A3: =W3 | B3: 43391659 | C3: Elia Caprile | E3: 23 | F3: 139 | G3: 144 | H3: =IFERROR(VLOOKUP(B3,球员对应球队!A:D,4,FALSE)-G3,"") -> 0 | I3: 154 | J3: GK | K3: 意大利 | L3: A. Bilbao | M3: =VLOOKUP(L3,信息总览!C:E,3,FALSE) -> 甲级 | P3: =IF(F3<115,1,INT((F3-95)/10)) -> 4 | Q3: =IF(G3<115,1,INT((G3-95)/10)) -> 4 | R3: =IF(I3<115,1,INT((I3-95)/10)) -> 5 | S3: =IF(E3>信息总览!$B$4,Q3,IF(I3<140,Q3,(Q3+R3)/2)) -> 4.5 | T3: =IF(AND(J3="GK",W3<>""),0.1,IF(S3=1,0.1,IF((S3+V3)/2=1,0.1,IF(W3="8M",0.15,IF(W3="7M",0.13,IF(W3="伪名",0.11,IF(E3>信息总览!$B$4,IF(INT((G3-95)/10)>5,0.09,0.07),IF(INT((I3-95)/10)>5,0.09,0.07)))))))) -> 0.07 | U3: =S3*T3 -> 0.315 | V3: =IF(E3>25,IF(F3<115,1,INT((F3-95)/10)),(IF(F3<115,1,INT((F3-95)/10))+IF(I3<115,1,INT((I3-95)/10)))/2) -> 4.5 | W3: =IF(V3>=8,"8M",IF(V3>=7,"7M",IF(E3<=信息总览!$B$4,IF(I3>164,"伪名",""),IF(AND(E3>信息总览!$B$4,E3<26,G3>164),"伪名","")))) | X3: =IF(I3<140,0,IF(E3>23,0,I3-G3)) -> 10
A4: =W4 | B4: 48032198 | C4: Evan N'Dicka | E4: 25 | F4: 154 | G4: 158 | H4: =IFERROR(VLOOKUP(B4,球员对应球队!A:D,4,FALSE)-G4,"") -> 0 | I4: 158 | J4: D/LC | K4: 科特迪瓦 | L4: A. Bilbao | M4: =VLOOKUP(L4,信息总览!C:E,3,FALSE) -> 甲级 | P4: =IF(F4<115,1,INT((F4-95)/10)) -> 5 | Q4: =IF(G4<115,1,INT((G4-95)/10)) -> 6 | R4: =IF(I4<115,1,INT((I4-95)/10)) -> 6 | S4: =IF(E4>信息总览!$B$4,Q4,IF(I4<140,Q4,(Q4+R4)/2)) -> 6 | T4: =IF(AND(J4="GK",W4<>""),0.1,IF(S4=1,0.1,IF((S4+V4)/2=1,0.1,IF(W4="8M",0.15,IF(W4="7M",0.13,IF(W4="伪名",0.11,IF(E4>信息总览!$B$4,IF(INT((G4-95)/10)>5,0.09,0.07),IF(INT((I4-95)/10)>5,0.09,0.07)))))))) -> 0.09 | U4: =S4*T4 -> 0.54 | V4: =IF(E4>25,IF(F4<115,1,INT((F4-95)/10)),(IF(F4<115,1,INT((F4-95)/10))+IF(I4<115,1,INT((I4-95)/10)))/2) -> 5.5 | W4: =IF(V4>=8,"8M",IF(V4>=7,"7M",IF(E4<=信息总览!$B$4,IF(I4>164,"伪名",""),IF(AND(E4>信息总览!$B$4,E4<26,G4>164),"伪名","")))) | X4: =IF(I4<140,0,IF(E4>23,0,I4-G4)) -> 0
A5: =W5 -> 伪名 | B5: 2000051578 | C5: Facundo Buonanotte | E5: 20 | F5: 133 | G5: 141 | H5: =IFERROR(VLOOKUP(B5,球员对应球队!A:D,4,FALSE)-G5,"") -> 0 | I5: 178 | J5: M/AMRLC | K5: Argentina,Italy | L5: A. Bilbao | M5: =VLOOKUP(L5,信息总览!C:E,3,FALSE) -> 甲级 | P5: =IF(F5<115,1,INT((F5-95)/10)) -> 3 | Q5: =IF(G5<115,1,INT((G5-95)/10)) -> 4 | R5: =IF(I5<115,1,INT((I5-95)/10)) -> 8 | S5: =IF(E5>信息总览!$B$4,Q5,IF(I5<140,Q5,(Q5+R5)/2)) -> 6 | T5: =IF(AND(J5="GK",W5<>""),0.1,IF(S5=1,0.1,IF((S5+V5)/2=1,0.1,IF(W5="8M",0.15,IF(W5="7M",0.13,IF(W5="伪名",0.11,IF(E5>信息总览!$B$4,IF(INT((G5-95)/10)>5,0.09,0.07),IF(INT((I5-95)/10)>5,0.09,0.07)))))))) -> 0.11 | U5: =S5*T5 -> 0.66 | V5: =IF(E5>25,IF(F5<115,1,INT((F5-95)/10)),(IF(F5<115,1,INT((F5-95)/10))+IF(I5<115,1,INT((I5-95)/10)))/2) -> 5.5 | W5: =IF(V5>=8,"8M",IF(V5>=7,"7M",IF(E5<=信息总览!$B$4,IF(I5>164,"伪名",""),IF(AND(E5>信息总览!$B$4,E5<26,G5>164),"伪名","")))) -> 伪名 | X5: =IF(I5<140,0,IF(E5>23,0,I5-G5)) -> 37
A6: =W6 -> 8M | B6: 28049320 | C6: Harry Kane | E6: 31 | F6: 188 | G6: 188 | H6: =IFERROR(VLOOKUP(B6,球员对应球队!A:D,4,FALSE)-G6,"") -> 0 | I6: 190 | J6: ST | K6: 英格兰 | L6: A. Bilbao | M6: =VLOOKUP(L6,信息总览!C:E,3,FALSE) -> 甲级 | P6: =IF(F6<115,1,INT((F6-95)/10)) -> 9 | Q6: =IF(G6<115,1,INT((G6-95)/10)) -> 9 | R6: =IF(I6<115,1,INT((I6-95)/10)) -> 9 | S6: =IF(E6>信息总览!$B$4,Q6,IF(I6<140,Q6,(Q6+R6)/2)) -> 9 | T6: =IF(AND(J6="GK",W6<>""),0.1,IF(S6=1,0.1,IF((S6+V6)/2=1,0.1,IF(W6="8M",0.15,IF(W6="7M",0.13,IF(W6="伪名",0.11,IF(E6>信息总览!$B$4,IF(INT((G6-95)/10)>5,0.09,0.07),IF(INT((I6-95)/10)>5,0.09,0.07)))))))) -> 0.15 | U6: =S6*T6 -> 1.35 | V6: =IF(E6>25,IF(F6<115,1,INT((F6-95)/10)),(IF(F6<115,1,INT((F6-95)/10))+IF(I6<115,1,INT((I6-95)/10)))/2) -> 9 | W6: =IF(V6>=8,"8M",IF(V6>=7,"7M",IF(E6<=信息总览!$B$4,IF(I6>164,"伪名",""),IF(AND(E6>信息总览!$B$4,E6<26,G6>164),"伪名","")))) -> 8M | X6: =IF(I6<140,0,IF(E6>23,0,I6-G6)) -> 0
A7: =W7 | B7: 67153377 | C7: Jose Suarez | E7: 29 | F7: 102 | G7: 102 | H7: =IFERROR(VLOOKUP(B7,球员对应球队!A:D,4,FALSE)-G7,"") -> 0 | I7: 120 | J7: GK | K7: 西班牙 | L7: A. Bilbao | M7: =VLOOKUP(L7,信息总览!C:E,3,FALSE) -> 甲级 | P7: =IF(F7<115,1,INT((F7-95)/10)) -> 1 | Q7: =IF(G7<115,1,INT((G7-95)/10)) -> 1 | R7: =IF(I7<115,1,INT((I7-95)/10)) -> 2 | S7: =IF(E7>信息总览!$B$4,Q7,IF(I7<140,Q7,(Q7+R7)/2)) -> 1 | T7: =IF(AND(J7="GK",W7<>""),0.1,IF(S7=1,0.1,IF((S7+V7)/2=1,0.1,IF(W7="8M",0.15,IF(W7="7M",0.13,IF(W7="伪名",0.11,IF(E7>信息总览!$B$4,IF(INT((G7-95)/10)>5,0.09,0.07),IF(INT((I7-95)/10)>5,0.09,0.07)))))))) -> 0.1 | U7: =S7*T7 -> 0.1 | V7: =IF(E7>25,IF(F7<115,1,INT((F7-95)/10)),(IF(F7<115,1,INT((F7-95)/10))+IF(I7<115,1,INT((I7-95)/10)))/2) -> 1 | W7: =IF(V7>=8,"8M",IF(V7>=7,"7M",IF(E7<=信息总览!$B$4,IF(I7>164,"伪名",""),IF(AND(E7>信息总览!$B$4,E7<26,G7>164),"伪名","")))) | X7: =IF(I7<140,0,IF(E7>23,0,I7-G7)) -> 0
A8: =W8 | B8: 2000241413 | C8: Kirill Glebov | E8: 19 | F8: 120 | G8: 149 | H8: =IFERROR(VLOOKUP(B8,球员对应球队!A:D,4,FALSE)-G8,"") -> 0 | I8: 160 | J8: AM/RLC | K8: Russia | L8: A. Bilbao | M8: =VLOOKUP(L8,信息总览!C:E,3,FALSE) -> 甲级 | P8: =IF(F8<115,1,INT((F8-95)/10)) -> 2 | Q8: =IF(G8<115,1,INT((G8-95)/10)) -> 5 | R8: =IF(I8<115,1,INT((I8-95)/10)) -> 6 | S8: =IF(E8>信息总览!$B$4,Q8,IF(I8<140,Q8,(Q8+R8)/2)) -> 5.5 | T8: =IF(AND(J8="GK",W8<>""),0.1,IF(S8=1,0.1,IF((S8+V8)/2=1,0.1,IF(W8="8M",0.15,IF(W8="7M",0.13,IF(W8="伪名",0.11,IF(E8>信息总览!$B$4,IF(INT((G8-95)/10)>5,0.09,0.07),IF(INT((I8-95)/10)>5,0.09,0.07)))))))) -> 0.09 | U8: =S8*T8 -> 0.495 | V8: =IF(E8>25,IF(F8<115,1,INT((F8-95)/10)),(IF(F8<115,1,INT((F8-95)/10))+IF(I8<115,1,INT((I8-95)/10)))/2) -> 4 | W8: =IF(V8>=8,"8M",IF(V8>=7,"7M",IF(E8<=信息总览!$B$4,IF(I8>164,"伪名",""),IF(AND(E8>信息总览!$B$4,E8<26,G8>164),"伪名","")))) | X8: =IF(I8<140,0,IF(E8>23,0,I8-G8)) -> 11
A9: =W9 | B9: 36096824 | C9: Kostas Tsimikas | E9: 29 | F9: 149 | G9: 149 | H9: =IFERROR(VLOOKUP(B9,球员对应球队!A:D,4,FALSE)-G9,"") -> 0 | I9: 159 | J9: D/WB/L | K9: 希腊 | L9: A. Bilbao | M9: =VLOOKUP(L9,信息总览!C:E,3,FALSE) -> 甲级 | P9: =IF(F9<115,1,INT((F9-95)/10)) -> 5 | Q9: =IF(G9<115,1,INT((G9-95)/10)) -> 5 | R9: =IF(I9<115,1,INT((I9-95)/10)) -> 6 | S9: =IF(E9>信息总览!$B$4,Q9,IF(I9<140,Q9,(Q9+R9)/2)) -> 5 | T9: =IF(AND(J9="GK",W9<>""),0.1,IF(S9=1,0.1,IF((S9+V9)/2=1,0.1,IF(W9="8M",0.15,IF(W9="7M",0.13,IF(W9="伪名",0.11,IF(E9>信息总览!$B$4,IF(INT((G9-95)/10)>5,0.09,0.07),IF(INT((I9-95)/10)>5,0.09,0.07)))))))) -> 0.07 | U9: =S9*T9 -> 0.35 | V9: =IF(E9>25,IF(F9<115,1,INT((F9-95)/10)),(IF(F9<115,1,INT((F9-95)/10))+IF(I9<115,1,INT((I9-95)/10)))/2) -> 5 | W9: =IF(V9>=8,"8M",IF(V9>=7,"7M",IF(E9<=信息总览!$B$4,IF(I9>164,"伪名",""),IF(AND(E9>信息总览!$B$4,E9<26,G9>164),"伪名","")))) | X9: =IF(I9<140,0,IF(E9>23,0,I9-G9)) -> 0
A10: =W10 -> 伪名 | B10: 2000298715 | C10: Mikey Moore | E10: 17 | F10: 124 | G10: 131 | H10: =IFERROR(VLOOKUP(B10,球员对应球队!A:D,4,FALSE)-G10,"") -> 0 | I10: 169 | J10: AM/RLC | K10: England,Wales | L10: A. Bilbao | M10: =VLOOKUP(L10,信息总览!C:E,3,FALSE) -> 甲级 | P10: =IF(F10<115,1,INT((F10-95)/10)) -> 2 | Q10: =IF(G10<115,1,INT((G10-95)/10)) -> 3 | R10: =IF(I10<115,1,INT((I10-95)/10)) -> 7 | S10: =IF(E10>信息总览!$B$4,Q10,IF(I10<140,Q10,(Q10+R10)/2)) -> 5 | T10: =IF(AND(J10="GK",W10<>""),0.1,IF(S10=1,0.1,IF((S10+V10)/2=1,0.1,IF(W10="8M",0.15,IF(W10="7M",0.13,IF(W10="伪名",0.11,IF(E10>信息总览!$B$4,IF(INT((G10-95)/10)>5,0.09,0.07),IF(INT((I10-95)/10)>5,0.09,0.07)))))))) -> 0.11 | U10: =S10*T10 -> 0.55 | V10: =IF(E10>25,IF(F10<115,1,INT((F10-95)/10)),(IF(F10<115,1,INT((F10-95)/10))+IF(I10<115,1,INT((I10-95)/10)))/2) -> 4.5 | W10: =IF(V10>=8,"8M",IF(V10>=7,"7M",IF(E10<=信息总览!$B$4,IF(I10>164,"伪名",""),IF(AND(E10>信息总览!$B$4,E10<26,G10>164),"伪名","")))) -> 伪名 | X10: =IF(I10<140,0,IF(E10>23,0,I10-G10)) -> 38
A11: =W11 -> 伪名 | B11: 2000254793 | C11: Nypan | E11: 18 | F11: 120 | G11: 140 | H11: =IFERROR(VLOOKUP(B11,球员对应球队!A:D,4,FALSE)-G11,"") -> 0 | I11: 179 | J11: M/AMRLC | K11: 丹麦 | L11: A. Bilbao | M11: =VLOOKUP(L11,信息总览!C:E,3,FALSE) -> 甲级 | P11: =IF(F11<115,1,INT((F11-95)/10)) -> 2 | Q11: =IF(G11<115,1,INT((G11-95)/10)) -> 4 | R11: =IF(I11<115,1,INT((I11-95)/10)) -> 8 | S11: =IF(E11>信息总览!$B$4,Q11,IF(I11<140,Q11,(Q11+R11)/2)) -> 6 | T11: =IF(AND(J11="GK",W11<>""),0.1,IF(S11=1,0.1,IF((S11+V11)/2=1,0.1,IF(W11="8M",0.15,IF(W11="7M",0.13,IF(W11="伪名",0.11,IF(E11>信息总览!$B$4,IF(INT((G11-95)/10)>5,0.09,0.07),IF(INT((I11-95)/10)>5,0.09,0.07)))))))) -> 0.11 | U11: =S11*T11 -> 0.66 | V11: =IF(E11>25,IF(F11<115,1,INT((F11-95)/10)),(IF(F11<115,1,INT((F11-95)/10))+IF(I11<115,1,INT((I11-95)/10)))/2) -> 5 | W11: =IF(V11>=8,"8M",IF(V11>=7,"7M",IF(E11<=信息总览!$B$4,IF(I11>164,"伪名",""),IF(AND(E11>信息总览!$B$4,E11<26,G11>164),"伪名","")))) -> 伪名 | X11: =IF(I11<140,0,IF(E11>23,0,I11-G11)) -> 39
A12: =W12 | B12: 2000466343 | C12: Olivier Mambwa | E12: 16 | F12: 89 | G12: 107 | H12: =IFERROR(VLOOKUP(B12,球员对应球队!A:D,4,FALSE)-G12,"") -> 0 | I12: 160 | J12: D/L | K12: Switzerland,Democratic Republic of Congo | L12: A. Bilbao | M12: =VLOOKUP(L12,信息总览!C:E,3,FALSE) -> 甲级 | P12: =IF(F12<115,1,INT((F12-95)/10)) -> 1 | Q12: =IF(G12<115,1,INT((G12-95)/10)) -> 1 | R12: =IF(I12<115,1,INT((I12-95)/10)) -> 6 | S12: =IF(E12>信息总览!$B$4,Q12,IF(I12<140,Q12,(Q12+R12)/2)) -> 3.5 | T12: =IF(AND(J12="GK",W12<>""),0.1,IF(S12=1,0.1,IF((S12+V12)/2=1,0.1,IF(W12="8M",0.15,IF(W12="7M",0.13,IF(W12="伪名",0.11,IF(E12>信息总览!$B$4,IF(INT((G12-95)/10)>5,0.09,0.07),IF(INT((I12-95)/10)>5,0.09,0.07)))))))) -> 0.09 | U12: =S12*T12 -> 0.315 | V12: =IF(E12>25,IF(F12<115,1,INT((F12-95)/10)),(IF(F12<115,1,INT((F12-95)/10))+IF(I12<115,1,INT((I12-95)/10)))/2) -> 3.5 | W12: =IF(V12>=8,"8M",IF(V12>=7,"7M",IF(E12<=信息总览!$B$4,IF(I12>164,"伪名",""),IF(AND(E12>信息总览!$B$4,E12<26,G12>164),"伪名","")))) | X12: =IF(I12<140,0,IF(E12>23,0,I12-G12)) -> 53
A13: =W13 | B13: 14094572 | C13: Rodrigo Bentancur | E13: 28 | F13: 150 | G13: 150 | H13: =IFERROR(VLOOKUP(B13,球员对应球队!A:D,4,FALSE)-G13,"") -> 0 | I13: 164 | J13: DM/MC | K13: 乌拉圭 | L13: A. Bilbao | M13: =VLOOKUP(L13,信息总览!C:E,3,FALSE) -> 甲级 | P13: =IF(F13<115,1,INT((F13-95)/10)) -> 5 | Q13: =IF(G13<115,1,INT((G13-95)/10)) -> 5 | R13: =IF(I13<115,1,INT((I13-95)/10)) -> 6 | S13: =IF(E13>信息总览!$B$4,Q13,IF(I13<140,Q13,(Q13+R13)/2)) -> 5 | T13: =IF(AND(J13="GK",W13<>""),0.1,IF(S13=1,0.1,IF((S13+V13)/2=1,0.1,IF(W13="8M",0.15,IF(W13="7M",0.13,IF(W13="伪名",0.11,IF(E13>信息总览!$B$4,IF(INT((G13-95)/10)>5,0.09,0.07),IF(INT((I13-95)/10)>5,0.09,0.07)))))))) -> 0.07 | U13: =S13*T13 -> 0.35 | V13: =IF(E13>25,IF(F13<115,1,INT((F13-95)/10)),(IF(F13<115,1,INT((F13-95)/10))+IF(I13<115,1,INT((I13-95)/10)))/2) -> 5 | W13: =IF(V13>=8,"8M",IF(V13>=7,"7M",IF(E13<=信息总览!$B$4,IF(I13>164,"伪名",""),IF(AND(E13>信息总览!$B$4,E13<26,G13>164),"伪名","")))) | X13: =IF(I13<140,0,IF(E13>23,0,I13-G13)) -> 0
... A35: =W35 | B35: 14048328 | C35: Juan Musso | E35: 31 | F35: 140 | G35: 140 | H35: =IFERROR(VLOOKUP(B35,球员对应球队!A:D,4,FALSE)-G35,"") -> 0 | I35: 149 | J35: GK | K35: 阿根廷 | L35: A. Madrid | M35: =VLOOKUP(L35,信息总览!C:E,3,FALSE) -> 甲级 | P35: =IF(F35<115,1,INT((F35-95)/10)) -> 4 | Q35: =IF(G35<115,1,INT((G35-95)/10)) -> 4 | R35: =IF(I35<115,1,INT((I35-95)/10)) -> 5 | S35: =IF(E35>信息总览!$B$4,Q35,IF(I35<140,Q35,(Q35+R35)/2)) -> 4 | T35: =IF(AND(J35="GK",W35<>""),0.1,IF(S35=1,0.1,IF((S35+V35)/2=1,0.1,IF(W35="8M",0.15,IF(W35="7M",0.13,IF(W35="伪名",0.11,IF(E35>信息总览!$B$4,IF(INT((G35-95)/10)>5,0.09,0.07),IF(INT((I35-95)/10)>5,0.09,0.07)))))))) -> 0.07 | U35: =S35*T35 -> 0.28 | V35: =IF(E35>25,IF(F35<115,1,INT((F35-95)/10)),(IF(F35<115,1,INT((F35-95)/10))+IF(I35<115,1,INT((I35-95)/10)))/2) -> 4 | W35: =IF(V35>=8,"8M",IF(V35>=7,"7M",IF(E35<=信息总览!$B$4,IF(I35>164,"伪名",""),IF(AND(E35>信息总览!$B$4,E35<26,G35>164),"伪名","")))) | X35: =IF(I35<140,0,IF(E35>23,0,I35-G35)) -> 0
A36: =W36 | B36: 2000221411 | C36: Allan | E36: 21 | F36: 115 | G36: 115 | I36: 139 | J36: M/AM RLC | K36: Brazil | L36: A. Madrid | M36: =VLOOKUP(L36,信息总览!C:E,3,FALSE) -> 甲级 | P36: =IF(F36<115,1,INT((F36-95)/10)) -> 2 | Q36: =IF(G36<115,1,INT((G36-95)/10)) -> 2 | R36: =IF(I36<115,1,INT((I36-95)/10)) -> 4 | S36: =IF(E36>信息总览!$B$4,Q36,IF(I36<140,Q36,(Q36+R36)/2)) -> 2 | T36: =IF(AND(J36="GK",W36<>""),0.1,IF(S36=1,0.1,IF((S36+V36)/2=1,0.1,IF(W36="8M",0.15,IF(W36="7M",0.13,IF(W36="伪名",0.11,IF(E36>信息总览!$B$4,IF(INT((G36-95)/10)>5,0.09,0.07),IF(INT((I36-95)/10)>5,0.09,0.07)))))))) -> 0.07 | U36: =S36*T36 -> 0.14 | V36: =IF(E36>25,IF(F36<115,1,INT((F36-95)/10)),(IF(F36<115,1,INT((F36-95)/10))+IF(I36<115,1,INT((I36-95)/10)))/2) -> 3 | W36: =IF(V36>=8,"8M",IF(V36>=7,"7M",IF(E36<=信息总览!$B$4,IF(I36>164,"伪名",""),IF(AND(E36>信息总览!$B$4,E36<26,G36>164),"伪名","")))) | X36: =IF(I36<140,0,IF(E36>23,0,I36-G36)) -> 0
A37: =W37 | B37: 29141472 | C37: Benjamin White | E37: 27 | F37: 155 | G37: 155 | I37: 162 | J37: D RC | K37: England | L37: A. Madrid | M37: =VLOOKUP(L37,信息总览!C:E,3,FALSE) -> 甲级 | P37: =IF(F37<115,1,INT((F37-95)/10)) -> 6 | Q37: =IF(G37<115,1,INT((G37-95)/10)) -> 6 | R37: =IF(I37<115,1,INT((I37-95)/10)) -> 6 | S37: =IF(E37>信息总览!$B$4,Q37,IF(I37<140,Q37,(Q37+R37)/2)) -> 6 | T37: =IF(AND(J37="GK",W37<>""),0.1,IF(S37=1,0.1,IF((S37+V37)/2=1,0.1,IF(W37="8M",0.15,IF(W37="7M",0.13,IF(W37="伪名",0.11,IF(E37>信息总览!$B$4,IF(INT((G37-95)/10)>5,0.09,0.07),IF(INT((I37-95)/10)>5,0.09,0.07)))))))) -> 0.09 | U37: =S37*T37 -> 0.54 | V37: =IF(E37>25,IF(F37<115,1,INT((F37-95)/10)),(IF(F37<115,1,INT((F37-95)/10))+IF(I37<115,1,INT((I37-95)/10)))/2) -> 6 | W37: =IF(V37>=8,"8M",IF(V37>=7,"7M",IF(E37<=信息总览!$B$4,IF(I37>164,"伪名",""),IF(AND(E37>信息总览!$B$4,E37<26,G37>164),"伪名","")))) | X37: =IF(I37<140,0,IF(E37>23,0,I37-G37)) -> 0
A38: =W38 -> 伪名 | B38: 2000094252 | C38: Beraldo | E38: 21 | F38: 142 | G38: 142 | H38: =IFERROR(VLOOKUP(B38,球员对应球队!A:D,4,FALSE)-G38,"") -> 0 | I38: 165 | J38: DC/DM | K38: 巴西 | L38: AC Milan | M38: =VLOOKUP(L38,信息总览!C:E,3,FALSE) -> 甲级 | P38: =IF(F38<115,1,INT((F38-95)/10)) -> 4 | Q38: =IF(G38<115,1,INT((G38-95)/10)) -> 4 | R38: =IF(I38<115,1,INT((I38-95)/10)) -> 7 | S38: =IF(E38>信息总览!$B$4,Q38,IF(I38<140,Q38,(Q38+R38)/2)) -> 5.5 | T38: =IF(AND(J38="GK",W38<>""),0.1,IF(S38=1,0.1,IF((S38+V38)/2=1,0.1,IF(W38="8M",0.15,IF(W38="7M",0.13,IF(W38="伪名",0.11,IF(E38>信息总览!$B$4,IF(INT((G38-95)/10)>5,0.09,0.07),IF(INT((I38-95)/10)>5,0.09,0.07)))))))) -> 0.11 | U38: =S38*T38 -> 0.605 | V38: =IF(E38>25,IF(F38<115,1,INT((F38-95)/10)),(IF(F38<115,1,INT((F38-95)/10))+IF(I38<115,1,INT((I38-95)/10)))/2) -> 5.5 | W38: =IF(V38>=8,"8M",IF(V38>=7,"7M",IF(E38<=信息总览!$B$4,IF(I38>164,"伪名",""),IF(AND(E38>信息总览!$B$4,E38<26,G38>164),"伪名","")))) -> 伪名 | X38: =IF(I38<140,0,IF(E38>23,0,I38-G38)) -> 23
A39: =W39 | B39: 2000094152 | C39: Claudio Echeverri | E39: 19 | F39: 123 | G39: 123 | H39: =IFERROR(VLOOKUP(B39,球员对应球队!A:D,4,FALSE)-G39,"") -> 0 | I39: 158 | J39: AM/RLC | K39: 阿根廷 | L39: AC Milan | M39: =VLOOKUP(L39,信息总览!C:E,3,FALSE) -> 甲级 | P39: =IF(F39<115,1,INT((F39-95)/10)) -> 2 | Q39: =IF(G39<115,1,INT((G39-95)/10)) -> 2 | R39: =IF(I39<115,1,INT((I39-95)/10)) -> 6 | S39: =IF(E39>信息总览!$B$4,Q39,IF(I39<140,Q39,(Q39+R39)/2)) -> 4 | T39: =IF(AND(J39="GK",W39<>""),0.1,IF(S39=1,0.1,IF((S39+V39)/2=1,0.1,IF(W39="8M",0.15,IF(W39="7M",0.13,IF(W39="伪名",0.11,IF(E39>信息总览!$B$4,IF(INT((G39-95)/10)>5,0.09,0.07),IF(INT((I39-95)/10)>5,0.09,0.07)))))))) -> 0.09 | U39: =S39*T39 -> 0.36 | V39: =IF(E39>25,IF(F39<115,1,INT((F39-95)/10)),(IF(F39<115,1,INT((F39-95)/10))+IF(I39<115,1,INT((I39-95)/10)))/2) -> 4 | W39: =IF(V39>=8,"8M",IF(V39>=7,"7M",IF(E39<=信息总览!$B$4,IF(I39>164,"伪名",""),IF(AND(E39>信息总览!$B$4,E39<26,G39>164),"伪名","")))) | X39: =IF(I39<140,0,IF(E39>23,0,I39-G39)) -> 35
A40: =W40 | B40: 43491384 | C40: Federico Gatti | E40: 27 | F40: 150 | G40: 150 | H40: =IFERROR(VLOOKUP(B40,球员对应球队!A:D,4,FALSE)-G40,"") -> 0 | I40: 153 | J40: D/C | K40: 意大利 | L40: AC Milan | M40: =VLOOKUP(L40,信息总览!C:E,3,FALSE) -> 甲级 | P40: =IF(F40<115,1,INT((F40-95)/10)) -> 5 | Q40: =IF(G40<115,1,INT((G40-95)/10)) -> 5 | R40: =IF(I40<115,1,INT((I40-95)/10)) -> 5 | S40: =IF(E40>信息总览!$B$4,Q40,IF(I40<140,Q40,(Q40+R40)/2)) -> 5 | T40: =IF(AND(J40="GK",W40<>""),0.1,IF(S40=1,0.1,IF((S40+V40)/2=1,0.1,IF(W40="8M",0.15,IF(W40="7M",0.13,IF(W40="伪名",0.11,IF(E40>信息总览!$B$4,IF(INT((G40-95)/10)>5,0.09,0.07),IF(INT((I40-95)/10)>5,0.09,0.07)))))))) -> 0.07 | U40: =S40*T40 -> 0.35 | V40: =IF(E40>25,IF(F40<115,1,INT((F40-95)/10)),(IF(F40<115,1,INT((F40-95)/10))+IF(I40<115,1,INT((I40-95)/10)))/2) -> 5 | W40: =IF(V40>=8,"8M",IF(V40>=7,"7M",IF(E40<=信息总览!$B$4,IF(I40>164,"伪名",""),IF(AND(E40>信息总览!$B$4,E40<26,G40>164),"伪名","")))) | X40: =IF(I40<140,0,IF(E40>23,0,I40-G40)) -> 0
A41: =W41 | B41: 2000293312 | C41: Jesús Fortea | E41: 18 | F41: 99 | G41: 99 | H41: =IFERROR(VLOOKUP(B41,球员对应球队!A:D,4,FALSE)-G41,"") -> 0 | I41: 155 | J41: D/WB/R | K41: 西班牙 | L41: AC Milan | M41: =VLOOKUP(L41,信息总览!C:E,3,FALSE) -> 甲级 | P41: =IF(F41<115,1,INT((F41-95)/10)) -> 1 | Q41: =IF(G41<115,1,INT((G41-95)/10)) -> 1 | R41: =IF(I41<115,1,INT((I41-95)/10)) -> 6 | S41: =IF(E41>信息总览!$B$4,Q41,IF(I41<140,Q41,(Q41+R41)/2)) -> 3.5 | T41: =IF(AND(J41="GK",W41<>""),0.1,IF(S41=1,0.1,IF((S41+V41)/2=1,0.1,IF(W41="8M",0.15,IF(W41="7M",0.13,IF(W41="伪名",0.11,IF(E41>信息总览!$B$4,IF(INT((G41-95)/10)>5,0.09,0.07),IF(INT((I41-95)/10)>5,0.09,0.07)))))))) -> 0.09 | U41: =S41*T41 -> 0.315 | V41: =IF(E41>25,IF(F41<115,1,INT((F41-95)/10)),(IF(F41<115,1,INT((F41-95)/10))+IF(I41<115,1,INT((I41-95)/10)))/2) -> 3.5 | W41: =IF(V41>=8,"8M",IF(V41>=7,"7M",IF(E41<=信息总览!$B$4,IF(I41>164,"伪名",""),IF(AND(E41>信息总览!$B$4,E41<26,G41>164),"伪名","")))) | X41: =IF(I41<140,0,IF(E41>23,0,I41-G41)) -> 56
A42: =W42 | B42: 2000299435 | C42: Joan | E42: 17 | F42: 86 | G42: 86 | H42: =IFERROR(VLOOKUP(B42,球员对应球队!A:D,4,FALSE)-G42,"") -> 0 | I42: 160 | J42: D/C | K42: 西班牙 | L42: AC Milan | M42: =VLOOKUP(L42,信息总览!C:E,3,FALSE) -> 甲级 | P42: =IF(F42<115,1,INT((F42-95)/10)) -> 1 | Q42: =IF(G42<115,1,INT((G42-95)/10)) -> 1 | R42: =IF(I42<115,1,INT((I42-95)/10)) -> 6 | S42: =IF(E42>信息总览!$B$4,Q42,IF(I42<140,Q42,(Q42+R42)/2)) -> 3.5 | T42: =IF(AND(J42="GK",W42<>""),0.1,IF(S42=1,0.1,IF((S42+V42)/2=1,0.1,IF(W42="8M",0.15,IF(W42="7M",0.13,IF(W42="伪名",0.11,IF(E42>信息总览!$B$4,IF(INT((G42-95)/10)>5,0.09,0.07),IF(INT((I42-95)/10)>5,0.09,0.07)))))))) -> 0.09 | U42: =S42*T42 -> 0.315 | V42: =IF(E42>25,IF(F42<115,1,INT((F42-95)/10)),(IF(F42<115,1,INT((F42-95)/10))+IF(I42<115,1,INT((I42-95)/10)))/2) -> 3.5 | W42: =IF(V42>=8,"8M",IF(V42>=7,"7M",IF(E42<=信息总览!$B$4,IF(I42>164,"伪名",""),IF(AND(E42>信息总览!$B$4,E42<26,G42>164),"伪名","")))) | X42: =IF(I42<140,0,IF(E42>23,0,I42-G42)) -> 74
A43: =W43 -> 伪名 | B43: 2000205927 | C43: Jobe Bellingham | E43: 19 | F43: 134 | G43: 141 | H43: =IFERROR(VLOOKUP(B43,球员对应球队!A:D,4,FALSE)-G43,"") -> 0 | I43: 167 | J43: M/AMC | K43: 英格兰 | L43: AC Milan | M43: =VLOOKUP(L43,信息总览!C:E,3,FALSE) -> 甲级 | P43: =IF(F43<115,1,INT((F43-95)/10)) -> 3 | Q43: =IF(G43<115,1,INT((G43-95)/10)) -> 4 | R43: =IF(I43<115,1,INT((I43-95)/10)) -> 7 | S43: =IF(E43>信息总览!$B$4,Q43,IF(I43<140,Q43,(Q43+R43)/2)) -> 5.5 | T43: =IF(AND(J43="GK",W43<>""),0.1,IF(S43=1,0.1,IF((S43+V43)/2=1,0.1,IF(W43="8M",0.15,IF(W43="7M",0.13,IF(W43="伪名",0.11,IF(E43>信息总览!$B$4,IF(INT((G43-95)/10)>5,0.09,0.07),IF(INT((I43-95)/10)>5,0.09,0.07)))))))) -> 0.11 | U43: =S43*T43 -> 0.605 | V43: =IF(E43>25,IF(F43<115,1,INT((F43-95)/10)),(IF(F43<115,1,INT((F43-95)/10))+IF(I43<115,1,INT((I43-95)/10)))/2) -> 5 | W43: =IF(V43>=8,"8M",IF(V43>=7,"7M",IF(E43<=信息总览!$B$4,IF(I43>164,"伪名",""),IF(AND(E43>信息总览!$B$4,E43<26,G43>164),"伪名","")))) -> 伪名 | X43: =IF(I43<140,0,IF(E43>23,0,I43-G43)) -> 26
A44: =W44 | B44: 58123738 | C44: Matvey Safonov | E44: 26 | F44: 140 | G44: 140 | H44: =IFERROR(VLOOKUP(B44,球员对应球队!A:D,4,FALSE)-G44,"") -> 0 | I44: 145 | J44: GK | K44: 英格兰 | L44: AC Milan | M44: =VLOOKUP(L44,信息总览!C:E,3,FALSE) -> 甲级 | P44: =IF(F44<115,1,INT((F44-95)/10)) -> 4 | Q44: =IF(G44<115,1,INT((G44-95)/10)) -> 4 | R44: =IF(I44<115,1,INT((I44-95)/10)) -> 5 | S44: =IF(E44>信息总览!$B$4,Q44,IF(I44<140,Q44,(Q44+R44)/2)) -> 4 | T44: =IF(AND(J44="GK",W44<>""),0.1,IF(S44=1,0.1,IF((S44+V44)/2=1,0.1,IF(W44="8M",0.15,IF(W44="7M",0.13,IF(W44="伪名",0.11,IF(E44>信息总览!$B$4,IF(INT((G44-95)/10)>5,0.09,0.07),IF(INT((I44-95)/10)>5,0.09,0.07)))))))) -> 0.07 | U44: =S44*T44 -> 0.28 | V44: =IF(E44>25,IF(F44<115,1,INT((F44-95)/10)),(IF(F44<115,1,INT((F44-95)/10))+IF(I44<115,1,INT((I44-95)/10)))/2) -> 4 | W44: =IF(V44>=8,"8M",IF(V44>=7,"7M",IF(E44<=信息总览!$B$4,IF(I44>164,"伪名",""),IF(AND(E44>信息总览!$B$4,E44<26,G44>164),"伪名","")))) | X44: =IF(I44<140,0,IF(E44>23,0,I44-G44)) -> 0
A45: =W45 | B45: 93127195 | C45: Odilon Kossounou | E45: 24 | F45: 144 | G45: 144 | H45: =IFERROR(VLOOKUP(B45,球员对应球队!A:D,4,FALSE)-G45,"") -> 0 | I45: 154 | J45: D/RC | K45: 科特迪瓦 | L45: AC Milan | M45: =VLOOKUP(L45,信息总览!C:E,3,FALSE) -> 甲级 | P45: =IF(F45<115,1,INT((F45-95)/10)) -> 4 | Q45: =IF(G45<115,1,INT((G45-95)/10)) -> 4 | R45: =IF(I45<115,1,INT((I45-95)/10)) -> 5 | S45: =IF(E45>信息总览!$B$4,Q45,IF(I45<140,Q45,(Q45+R45)/2)) -> 4.5 | T45: =IF(AND(J45="GK",W45<>""),0.1,IF(S45=1,0.1,IF((S45+V45)/2=1,0.1,IF(W45="8M",0.15,IF(W45="7M",0.13,IF(W45="伪名",0.11,IF(E45>信息总览!$B$4,IF(INT((G45-95)/10)>5,0.09,0.07),IF(INT((I45-95)/10)>5,0.09,0.07)))))))) -> 0.07 | U45: =S45*T45 -> 0.315 | V45: =IF(E45>25,IF(F45<115,1,INT((F45-95)/10)),(IF(F45<115,1,INT((F45-95)/10))+IF(I45<115,1,INT((I45-95)/10)))/2) -> 4.5 | W45: =IF(V45>=8,"8M",IF(V45>=7,"7M",IF(E45<=信息总览!$B$4,IF(I45>164,"伪名",""),IF(AND(E45>信息总览!$B$4,E45<26,G45>164),"伪名","")))) | X45: =IF(I45<140,0,IF(E45>23,0,I45-G45)) -> 0
A46: =W46 | B46: 2000095783 | C46: Vitor Roque | E46: 20 | F46: 138 | G46: 143 | H46: =IFERROR(VLOOKUP(B46,球员对应球队!A:D,4,FALSE)-G46,"") -> 0 | I46: 151 | J46: ST | K46: 巴西 | L46: AC Milan | M46: =VLOOKUP(L46,信息总览!C:E,3,FALSE) -> 甲级 | P46: =IF(F46<115,1,INT((F46-95)/10)) -> 4 | Q46: =IF(G46<115,1,INT((G46-95)/10)) -> 4 | R46: =IF(I46<115,1,INT((I46-95)/10)) -> 5 | S46: =IF(E46>信息总览!$B$4,Q46,IF(I46<140,Q46,(Q46+R46)/2)) -> 4.5 | T46: =IF(AND(J46="GK",W46<>""),0.1,IF(S46=1,0.1,IF((S46+V46)/2=1,0.1,IF(W46="8M",0.15,IF(W46="7M",0.13,IF(W46="伪名",0.11,IF(E46>信息总览!$B$4,IF(INT((G46-95)/10)>5,0.09,0.07),IF(INT((I46-95)/10)>5,0.09,0.07)))))))) -> 0.07 | U46: =S46*T46 -> 0.315 | V46: =IF(E46>25,IF(F46<115,1,INT((F46-95)/10)),(IF(F46<115,1,INT((F46-95)/10))+IF(I46<115,1,INT((I46-95)/10)))/2) -> 4.5 | W46: =IF(V46>=8,"8M",IF(V46>=7,"7M",IF(E46<=信息总览!$B$4,IF(I46>164,"伪名",""),IF(AND(E46>信息总览!$B$4,E46<26,G46>164),"伪名","")))) | X46: =IF(I46<140,0,IF(E46>23,0,I46-G46)) -> 8
A47: =W47 | B47: 1007737 | C47: Wang Dalei | E47: 36 | F47: 106 | G47: 106 | H47: =IFERROR(VLOOKUP(B47,球员对应球队!A:D,4,FALSE)-G47,"") -> 0 | I47: 118 | J47: GK | K47: 中国 | L47: AC Milan | M47: =VLOOKUP(L47,信息总览!C:E,3,FALSE) -> 甲级 | P47: =IF(F47<115,1,INT((F47-95)/10)) -> 1 | Q47: =IF(G47<115,1,INT((G47-95)/10)) -> 1 | R47: =IF(I47<115,1,INT((I47-95)/10)) -> 2 | S47: =IF(E47>信息总览!$B$4,Q47,IF(I47<140,Q47,(Q47+R47)/2)) -> 1 | T47: =IF(AND(J47="GK",W47<>""),0.1,IF(S47=1,0.1,IF((S47+V47)/2=1,0.1,IF(W47="8M",0.15,IF(W47="7M",0.13,IF(W47="伪名",0.11,IF(E47>信息总览!$B$4,IF(INT((G47-95)/10)>5,0.09,0.07),IF(INT((I47-95)/10)>5,0.09,0.07)))))))) -> 0.1 | U47: =S47*T47 -> 0.1 | V47: =IF(E47>25,IF(F47<115,1,INT((F47-95)/10)),(IF(F47<115,1,INT((F47-95)/10))+IF(I47<115,1,INT((I47-95)/10)))/2) -> 1 | W47: =IF(V47>=8,"8M",IF(V47>=7,"7M",IF(E47<=信息总览!$B$4,IF(I47>164,"伪名",""),IF(AND(E47>信息总览!$B$4,E47<26,G47>164),"伪名","")))) | X47: =IF(I47<140,0,IF(E47>23,0,I47-G47)) -> 0
A48: =W48 | B48: 67260204 | C48: Oihan Sancet | E48: 25 | F48: 156 | G48: 156 | H48: =IFERROR(VLOOKUP(B48,球员对应球队!A:D,4,FALSE)-G48,"") -> 0 | I48: 162 | J48: M/AMC | K48: 西班牙 | L48: AC Milan | M48: =VLOOKUP(L48,信息总览!C:E,3,FALSE) -> 甲级 | P48: =IF(F48<115,1,INT((F48-95)/10)) -> 6 | Q48: =IF(G48<115,1,INT((G48-95)/10)) -> 6 | R48: =IF(I48<115,1,INT((I48-95)/10)) -> 6 | S48: =IF(E48>信息总览!$B$4,Q48,IF(I48<140,Q48,(Q48+R48)/2)) -> 6 | T48: =IF(AND(J48="GK",W48<>""),0.1,IF(S48=1,0.1,IF((S48+V48)/2=1,0.1,IF(W48="8M",0.15,IF(W48="7M",0.13,IF(W48="伪名",0.11,IF(E48>信息总览!$B$4,IF(INT((G48-95)/10)>5,0.09,0.07),IF(INT((I48-95)/10)>5,0.09,0.07)))))))) -> 0.09 | U48: =S48*T48 -> 0.54 | V48: =IF(E48>25,IF(F48<115,1,INT((F48-95)/10)),(IF(F48<115,1,INT((F48-95)/10))+IF(I48<115,1,INT((I48-95)/10)))/2) -> 6 | W48: =IF(V48>=8,"8M",IF(V48>=7,"7M",IF(E48<=信息总览!$B$4,IF(I48>164,"伪名",""),IF(AND(E48>信息总览!$B$4,E48<26,G48>164),"伪名","")))) | X48: =IF(I48<140,0,IF(E48>23,0,I48-G48)) -> 0
A49: =W49 | B49: 76063258 | C49: Jhon Durán | E49: 21 | F49: 130 | G49: 130 | H49: =IFERROR(VLOOKUP(B49,球员对应球队!A:D,4,FALSE)-G49,"") -> 0 | I49: 150 | J49: ST | K49: 哥伦比亚 | L49: AC Milan | M49: =VLOOKUP(L49,信息总览!C:E,3,FALSE) -> 甲级 | P49: =IF(F49<115,1,INT((F49-95)/10)) -> 3 | Q49: =IF(G49<115,1,INT((G49-95)/10)) -> 3 | R49: =IF(I49<115,1,INT((I49-95)/10)) -> 5 | S49: =IF(E49>信息总览!$B$4,Q49,IF(I49<140,Q49,(Q49+R49)/2)) -> 4 | T49: =IF(AND(J49="GK",W49<>""),0.1,IF(S49=1,0.1,IF((S49+V49)/2=1,0.1,IF(W49="8M",0.15,IF(W49="7M",0.13,IF(W49="伪名",0.11,IF(E49>信息总览!$B$4,IF(INT((G49-95)/10)>5,0.09,0.07),IF(INT((I49-95)/10)>5,0.09,0.07)))))))) -> 0.07 | U49: =S49*T49 -> 0.28 | V49: =IF(E49>25,IF(F49<115,1,INT((F49-95)/10)),(IF(F49<115,1,INT((F49-95)/10))+IF(I49<115,1,INT((I49-95)/10)))/2) -> 4 | W49: =IF(V49>=8,"8M",IF(V49>=7,"7M",IF(E49<=信息总览!$B$4,IF(I49>164,"伪名",""),IF(AND(E49>信息总览!$B$4,E49<26,G49>164),"伪名","")))) | X49: =IF(I49<140,0,IF(E49>23,0,I49-G49)) -> 20
... A128: =W128 | B128: 2000466272 | C128: Brian Madjo | E128: 16 | F128: 95 | G128: 95 | H128: =IFERROR(VLOOKUP(B128,球员对应球队!A:D,4,FALSE)-G128,"") -> 0 | I128: 160 | J128: ST | K128: England,Luxembourg,Cameroon | L128: Aston Villa | M128: =VLOOKUP(L128,信息总览!C:E,3,FALSE) -> 超级 | P128: =IF(F128<115,1,INT((F128-95)/10)) -> 1 | Q128: =IF(G128<115,1,INT((G128-95)/10)) -> 1 | R128: =IF(I128<115,1,INT((I128-95)/10)) -> 6 | S128: =IF(E128>信息总览!$B$4,Q128,IF(I128<140,Q128,(Q128+R128)/2)) -> 3.5 | T128: =IF(AND(J128="GK",W128<>""),0.1,IF(S128=1,0.1,IF((S128+V128)/2=1,0.1,IF(W128="8M",0.15,IF(W128="7M",0.13,IF(W128="伪名",0.11,IF(E128>信息总览!$B$4,IF(INT((G128-95)/10)>5,0.09,0.07),IF(INT((I128-95)/10)>5,0.09,0.07)))))))) -> 0.09 | U128: =S128*T128 -> 0.315 | V128: =IF(E128>25,IF(F128<115,1,INT((F128-95)/10)),(IF(F128<115,1,INT((F128-95)/10))+IF(I128<115,1,INT((I128-95)/10)))/2) -> 3.5 | W128: =IF(V128>=8,"8M",IF(V128>=7,"7M",IF(E128<=信息总览!$B$4,IF(I128>164,"伪名",""),IF(AND(E128>信息总览!$B$4,E128<26,G128>164),"伪名","")))) | X128: =IF(I128<140,0,IF(E128>23,0,I128-G128)) -> 65
A129: =W129 | B129: 2000277689 | C129: Alysson Edward | E129: 19 | F129: 115 | G129: 115 | I129: 150 | J129: AMRL | K129: 巴西 | L129: Aston Villa | M129: =VLOOKUP(L129,信息总览!C:E,3,FALSE) -> 超级 | P129: =IF(F129<115,1,INT((F129-95)/10)) -> 2 | Q129: =IF(G129<115,1,INT((G129-95)/10)) -> 2 | R129: =IF(I129<115,1,INT((I129-95)/10)) -> 5 | S129: =IF(E129>信息总览!$B$4,Q129,IF(I129<140,Q129,(Q129+R129)/2)) -> 3.5 | T129: =IF(AND(J129="GK",W129<>""),0.1,IF(S129=1,0.1,IF((S129+V129)/2=1,0.1,IF(W129="8M",0.15,IF(W129="7M",0.13,IF(W129="伪名",0.11,IF(E129>信息总览!$B$4,IF(INT((G129-95)/10)>5,0.09,0.07),IF(INT((I129-95)/10)>5,0.09,0.07)))))))) -> 0.07 | U129: =S129*T129 -> 0.245 | V129: =IF(E129>25,IF(F129<115,1,INT((F129-95)/10)),(IF(F129<115,1,INT((F129-95)/10))+IF(I129<115,1,INT((I129-95)/10)))/2) -> 3.5 | W129: =IF(V129>=8,"8M",IF(V129>=7,"7M",IF(E129<=信息总览!$B$4,IF(I129>164,"伪名",""),IF(AND(E129>信息总览!$B$4,E129<26,G129>164),"伪名","")))) | X129: =IF(I129<140,0,IF(E129>23,0,I129-G129)) -> 35
A130: =W130 -> 伪名 | B130: 67296654 | C130: Alejandro Balde | E130: 21 | F130: 153 | G130: 160 | H130: =IFERROR(VLOOKUP(B130,球员对应球队!A:D,4,FALSE)-G130,"") -> 0 | I130: 170 | J130: D/WB/M/AM/L | K130: 西班牙 | L130: Barcelona | M130: =VLOOKUP(L130,信息总览!C:E,3,FALSE) -> 超级 | P130: =IF(F130<115,1,INT((F130-95)/10)) -> 5 | Q130: =IF(G130<115,1,INT((G130-95)/10)) -> 6 | R130: =IF(I130<115,1,INT((I130-95)/10)) -> 7 | S130: =IF(E130>信息总览!$B$4,Q130,IF(I130<140,Q130,(Q130+R130)/2)) -> 6.5 | T130: =IF(AND(J130="GK",W130<>""),0.1,IF(S130=1,0.1,IF((S130+V130)/2=1,0.1,IF(W130="8M",0.15,IF(W130="7M",0.13,IF(W130="伪名",0.11,IF(E130>信息总览!$B$4,IF(INT((G130-95)/10)>5,0.09,0.07),IF(INT((I130-95)/10)>5,0.09,0.07)))))))) -> 0.11 | U130: =S130*T130 -> 0.715 | V130: =IF(E130>25,IF(F130<115,1,INT((F130-95)/10)),(IF(F130<115,1,INT((F130-95)/10))+IF(I130<115,1,INT((I130-95)/10)))/2) -> 6 | W130: =IF(V130>=8,"8M",IF(V130>=7,"7M",IF(E130<=信息总览!$B$4,IF(I130>164,"伪名",""),IF(AND(E130>信息总览!$B$4,E130<26,G130>164),"伪名","")))) -> 伪名 | X130: =IF(I130<140,0,IF(E130>23,0,I130-G130)) -> 10
A131: =W131 | B131: 67221484 | C131: Iñaki Peña | E131: 26 | F131: 138 | G131: 138 | H131: =IFERROR(VLOOKUP(B131,球员对应球队!A:D,4,FALSE)-G131,"") -> 0 | I131: 150 | J131: GK | K131: 西班牙 | L131: Barcelona | M131: =VLOOKUP(L131,信息总览!C:E,3,FALSE) -> 超级 | P131: =IF(F131<115,1,INT((F131-95)/10)) -> 4 | Q131: =IF(G131<115,1,INT((G131-95)/10)) -> 4 | R131: =IF(I131<115,1,INT((I131-95)/10)) -> 5 | S131: =IF(E131>信息总览!$B$4,Q131,IF(I131<140,Q131,(Q131+R131)/2)) -> 4 | T131: =IF(AND(J131="GK",W131<>""),0.1,IF(S131=1,0.1,IF((S131+V131)/2=1,0.1,IF(W131="8M",0.15,IF(W131="7M",0.13,IF(W131="伪名",0.11,IF(E131>信息总览!$B$4,IF(INT((G131-95)/10)>5,0.09,0.07),IF(INT((I131-95)/10)>5,0.09,0.07)))))))) -> 0.07 | U131: =S131*T131 -> 0.28 | V131: =IF(E131>25,IF(F131<115,1,INT((F131-95)/10)),(IF(F131<115,1,INT((F131-95)/10))+IF(I131<115,1,INT((I131-95)/10)))/2) -> 4 | W131: =IF(V131>=8,"8M",IF(V131>=7,"7M",IF(E131<=信息总览!$B$4,IF(I131>164,"伪名",""),IF(AND(E131>信息总览!$B$4,E131<26,G131>164),"伪名","")))) | X131: =IF(I131<140,0,IF(E131>23,0,I131-G131)) -> 0
